File: [DEIM][DCA].txt
Filename	313IL2
Instrument name	DSC2-01590 (192.168.1.10)
Operator
rundate	2025/3/13
Sample name	313IL2
proceduresegments	Ramp 1.00 °C/min to -50.00 °C; Isothermal 60.0 min; Ramp 1.00 °C/min to 50.00 °C
[File Parameters]
Run date	2025/3/13 18:21:40
Trios version	5.1.1.46572
Original File Name
Current File Name	C:\ProgramData\TA Instruments\TRIOS\Data\313IL2.tri
[Procedure]
Procedure Name
Sample Name	313IL2
Sample Mass	8 mg
Pan Mass	0 mg
Pan Number	0
Reference Pan Number	0
Pan Type	Tzero Aluminum Hermetic
Comments
Project Name
Operator
Test	Custom
Unload Max Temperature	30
Unload Min Temperature	30
Load Max Temperature	30
Load Min Temperature	30
Stop on Gas Flow Error	Yes
[Signal List]
Signal #1	Time (min)
Signal #2	Temperature (°C)
Signal #3	Heat Flow (mW)
Signal #4	Delta T (µV)
Signal #5	Delta Tzero (µV)
Signal #6	Tzero Temperature (°C)
Signal #7	Cell Purge (mL/min)
Signal #8	Heater Temp (°C)
Signal #9	Power Delivered (W)
Signal #10	Reference Junction Temperature (°C)
Signal #11	Flange Temperature (°C)
Signal #12	Heat Flow Phase (rad)
Signal #13	Total Heat Capacity (J/°C)
[Configuration]
Company Name	ta
Instrument Name	DSC2-01590
Instrument Type	DSC25
Serial Number	DSC2-01590
IP	192.168.1.10
Location of Instrument	MFG
DisplayType	TianmaV2
Sample Interval 	0.1 s/pt
Selected Heat Flow	T1
Exotherm Direction	Up
Cell Serial	DRC2-03531
Lid Type	High Temperature
Cooler	RCS 90
Leave Cooler on at End of Sequence	On
Gas 2	Air
Gas Selected	Channel 1
Flow Rate	50 mL/min
Secondary Purge	Off
Licensed Heat Flow	Heat Flow T1
Modulation Licensed	Yes
[Versions]
Common IDD Version	1
Cortex Version	VER 2.10.2.31
Driver	5.0.0.6
GDM Version	1.0.3.3
TouchscreenVersion	1.0.0.16145
FEP Version	1.2.1.21
FEP Bootloader	2.0.0.5
FCM Version	1.1.0.3
FCM Bootloader	2.0.0.5
[Experiment Logs]
Experiment Log Entry # 1	Air Cool is off.
Experiment Log Entry # 3	Ramp Segment 1 C/min to -50 Started
Experiment Log Entry # 5	Isothermal Segment 60 min started
Experiment Log Entry # 7	Ramp Segment 1 C/min to 50 Started
Experiment Log Entry # 9	Ramp Segment 5 C/min to 50 Started
Experiment Log Entry # 11	User modified running procedure
Experiment Log Entry # 13	Ramp Segment 10 C/min to 50 Started
Experiment Log Entry # 15	User modified running procedure
[Method Log]
Method Log Entry # 1	(Ramp 14184) Ramp 1 °C/minute to -50 °C
Method Log Entry # 2	Isothermal 60 minutes
Method Log Entry # 3	(Ramp 14186) Ramp 10 °C/minute to 50 °C
Cell Serial	DRC2-03531
[T1 Calibration]
Date Applied	2022/8/30 17:06:21
Description	From -40.140 °C to 349.984 °C at 20.000°C/min
Gas Type	Nitrogen
Pan Type	None
Source Files 1	C:\ProgramData\TA Instruments\TRIOS\Data\Default(71).tri
Slope	-0.004052628
Offset	7.523911
Initial Temperature	-40.14014
GUID	1c40c2ec-416b-49dd-97cd-b9bbe1fdbf85
[TZero Calibration]
(Not Applied)
[Temperature Calibration]
Date Applied	2022/8/30 18:06:51
Description	From 106.590 °C to 186.590 °C at 10.000°C/min
Gas Type	Nitrogen
Pan Type	Tzero Aluminum Hermetic
Source Files 1	C:\ProgramData\TA Instruments\TRIOS\Data\Indium(6).tri
Measured 1	158.5283
Known 1	156.598
[Cell Constant Calibration]
Date Applied	2022/8/30 18:06:51
Description	From 106.590 °C to 186.590 °C at 10.000°C/min
Gas Type	Nitrogen
Pan Type	Tzero Aluminum Hermetic
Source Files 1	C:\ProgramData\TA Instruments\TRIOS\Data\Indium(6).tri
T1 KCell	0.9221585
Onset Slope	-7.918681 mW/°C
[Direct Cp Calibration]
(Not Applied)
[Rev Cp Calibration]
(Not Applied)
[step]
Ramp 1.00 °C/min to -50.00 °C
Time	Temperature	Heat Flow (Normalized)
min	°C	W/g
0.00
0.05	30.03
0.11	30.02	-0.016
0.16	29.99	-0.011
0.22	29.94	-0.003
0.28	29.90	0.003
0.33	29.85	0.007
0.39	29.79	0.010
0.44	29.74	0.011
0.50	29.68	0.012
0.55	29.63	0.013
0.60	29.58	0.013
0.66	29.52	0.014
0.72	29.47	0.014
0.77	29.41	0.015
0.83	29.36	0.015
0.88	29.30	0.016
0.93	29.25	0.016
0.99	29.19	0.016
1.05	29.14	0.016
1.10	29.08	0.016
1.16	29.03	0.017
1.21	28.97	0.017
1.27	28.92	0.017
1.32	28.86	0.017
1.38	28.81	0.017
1.43	28.75	0.017
1.48	28.70	0.017
1.54	28.64	0.017
1.59	28.59	0.017
1.65	28.53	0.017
1.71	28.48	0.017
1.76	28.42	0.017
1.82	28.37	0.017
1.87	28.31	0.017
1.93	28.26	0.017
1.98	28.20	0.017
2.03	28.15	0.017
2.09	28.09	0.017
2.14	28.04	0.017
2.20	27.98	0.017
2.26	27.93	0.017
2.31	27.87	0.017
2.36	27.82	0.017
2.42	27.76	0.017
2.48	27.71	0.017
2.53	27.65	0.017
2.59	27.60	0.017
2.64	27.54	0.017
2.69	27.49	0.017
2.75	27.43	0.017
2.81	27.38	0.017
2.86	27.32	0.017
2.91	27.27	0.017
2.97	27.21	0.017
3.03	27.16	0.017
3.08	27.10	0.017
3.14	27.05	0.018
3.19	26.99	0.018
3.24	26.94	0.018
3.30	26.88	0.018
3.36	26.83	0.018
3.41	26.78	0.018
3.46	26.72	0.018
3.52	26.67	0.018
3.58	26.61	0.018
3.63	26.55	0.018
3.69	26.50	0.018
3.74	26.45	0.018
3.79	26.39	0.018
3.85	26.34	0.018
3.91	26.28	0.018
3.96	26.22	0.018
4.01	26.17	0.018
4.07	26.11	0.018
4.13	26.06	0.018
4.18	26.00	0.018
4.24	25.95	0.018
4.29	25.90	0.018
4.35	25.84	0.018
4.40	25.79	0.018
4.45	25.73	0.018
4.51	25.67	0.018
4.56	25.62	0.018
4.62	25.56	0.018
4.68	25.51	0.018
4.73	25.46	0.018
4.79	25.40	0.018
4.84	25.35	0.018
4.90	25.29	0.018
4.95	25.24	0.018
5.00	25.18	0.018
5.06	25.13	0.018
5.11	25.07	0.018
5.17	25.02	0.018
5.23	24.96	0.018
5.28	24.91	0.018
5.34	24.85	0.018
5.39	24.80	0.018
5.45	24.74	0.018
5.50	24.69	0.018
5.55	24.63	0.018
5.61	24.58	0.018
5.66	24.52	0.017
5.72	24.47	0.017
5.78	24.41	0.017
5.83	24.36	0.017
5.89	24.30	0.017
5.94	24.25	0.017
6.00	24.19	0.017
6.05	24.14	0.017
6.10	24.08	0.017
6.16	24.03	0.017
6.21	23.97	0.017
6.27	23.92	0.017
6.33	23.86	0.017
6.38	23.81	0.017
6.44	23.75	0.017
6.49	23.70	0.017
6.55	23.64	0.017
6.60	23.59	0.017
6.65	23.53	0.017
6.71	23.48	0.017
6.76	23.42	0.017
6.82	23.37	0.017
6.88	23.31	0.017
6.93	23.26	0.017
6.99	23.20	0.017
7.04	23.15	0.017
7.10	23.09	0.017
7.15	23.04	0.017
7.20	22.98	0.017
7.26	22.93	0.017
7.31	22.87	0.017
7.37	22.82	0.017
7.43	22.76	0.017
7.48	22.71	0.018
7.54	22.65	0.018
7.59	22.60	0.018
7.65	22.54	0.018
7.70	22.49	0.018
7.75	22.43	0.018
7.81	22.38	0.018
7.86	22.32	0.018
7.92	22.27	0.018
7.98	22.21	0.018
8.03	22.16	0.017
8.09	22.10	0.017
8.14	22.05	0.017
8.20	21.99	0.017
8.25	21.94	0.017
8.30	21.88	0.017
8.36	21.83	0.017
8.41	21.77	0.017
8.47	21.72	0.017
8.53	21.66	0.017
8.58	21.61	0.017
8.63	21.55	0.017
8.69	21.50	0.017
8.75	21.44	0.017
8.80	21.39	0.017
8.85	21.33	0.017
8.91	21.28	0.018
8.97	21.22	0.018
9.02	21.17	0.017
9.08	21.11	0.017
9.13	21.06	0.017
9.18	21.00	0.017
9.24	20.95	0.017
9.30	20.89	0.017
9.35	20.84	0.017
9.40	20.78	0.017
9.46	20.73	0.017
9.52	20.67	0.017
9.57	20.62	0.017
9.63	20.56	0.017
9.68	20.51	0.017
9.73	20.45	0.017
9.79	20.40	0.017
9.85	20.34	0.017
9.90	20.29	0.017
9.95	20.23	0.017
10.01	20.18	0.017
10.07	20.12	0.017
10.12	20.07	0.017
10.18	20.01	0.017
10.23	19.96	0.017
10.28	19.90	0.017
10.34	19.85	0.017
10.40	19.79	0.017
10.45	19.74	0.018
10.50	19.68	0.018
10.56	19.63	0.018
10.62	19.57	0.018
10.67	19.52	0.018
10.73	19.46	0.018
10.78	19.41	0.018
10.83	19.35	0.018
10.89	19.30	0.018
10.95	19.24	0.018
11.00	19.19	0.017
11.05	19.13	0.018
11.11	19.08	0.018
11.17	19.02	0.018
11.22	18.97	0.017
11.28	18.91	0.017
11.33	18.86	0.017
11.38	18.80	0.017
11.44	18.75	0.017
11.50	18.69	0.017
11.55	18.64	0.017
11.60	18.58	0.017
11.66	18.53	0.017
11.72	18.47	0.017
11.77	18.42	0.017
11.83	18.36	0.017
11.88	18.31	0.017
11.93	18.25	0.017
11.99	18.20	0.017
12.05	18.14	0.017
12.10	18.09	0.017
12.15	18.03	0.017
12.21	17.98	0.017
12.27	17.92	0.017
12.32	17.87	0.017
12.38	17.81	0.017
12.43	17.76	0.017
12.48	17.70	0.017
12.54	17.65	0.017
12.60	17.59	0.017
12.65	17.54	0.017
12.70	17.48	0.017
12.76	17.43	0.017
12.82	17.37	0.017
12.87	17.32	0.017
12.93	17.26	0.017
12.98	17.21	0.017
13.03	17.15	0.017
13.09	17.10	0.017
13.15	17.04	0.017
13.20	16.99	0.017
13.25	16.93	0.017
13.31	16.88	0.017
13.37	16.82	0.017
13.42	16.77	0.017
13.48	16.71	0.017
13.53	16.66	0.017
13.58	16.60	0.017
13.64	16.55	0.017
13.70	16.49	0.017
13.75	16.44	0.017
13.80	16.39	0.017
13.86	16.33	0.017
13.92	16.27	0.017
13.97	16.22	0.017
14.03	16.16	0.017
14.08	16.11	0.017
14.13	16.05	0.017
14.19	16.00	0.017
14.25	15.94	0.017
14.30	15.89	0.017
14.35	15.83	0.017
14.41	15.78	0.017
14.47	15.72	0.017
14.52	15.67	0.017
14.58	15.61	0.017
14.63	15.56	0.017
14.68	15.50	0.017
14.74	15.45	0.017
14.80	15.40	0.017
14.85	15.34	0.017
14.90	15.28	0.017
14.96	15.23	0.017
15.02	15.18	0.017
15.07	15.12	0.017
15.13	15.07	0.017
15.18	15.01	0.017
15.23	14.96	0.017
15.29	14.90	0.017
15.35	14.84	0.017
15.40	14.79	0.017
15.45	14.73	0.017
15.51	14.68	0.017
15.57	14.62	0.017
15.62	14.57	0.017
15.68	14.52	0.017
15.73	14.46	0.017
15.78	14.41	0.017
15.84	14.35	0.017
15.90	14.30	0.017
15.95	14.24	0.017
16.00	14.18	0.017
16.06	14.13	0.017
16.12	14.08	0.017
16.17	14.02	0.017
16.23	13.97	0.017
16.28	13.91	0.017
16.33	13.86	0.017
16.39	13.80	0.017
16.45	13.75	0.017
16.50	13.69	0.017
16.55	13.63	0.017
16.61	13.58	0.017
16.67	13.53	0.017
16.72	13.47	0.017
16.78	13.42	0.017
16.83	13.36	0.017
16.88	13.31	0.017
16.94	13.25	0.017
17.00	13.20	0.017
17.05	13.14	0.017
17.11	13.09	0.017
17.16	13.03	0.017
17.22	12.97	0.017
17.27	12.92	0.017
17.33	12.87	0.017
17.38	12.81	0.017
17.43	12.76	0.017
17.49	12.70	0.017
17.54	12.65	0.017
17.60	12.59	0.017
17.66	12.54	0.017
17.71	12.48	0.017
17.77	12.43	0.017
17.82	12.37	0.017
17.88	12.32	0.017
17.93	12.26	0.017
17.98	12.21	0.017
18.04	12.15	0.017
18.09	12.10	0.017
18.15	12.04	0.017
18.21	11.99	0.017
18.26	11.93	0.017
18.32	11.88	0.017
18.37	11.82	0.017
18.43	11.77	0.017
18.48	11.71	0.017
18.53	11.66	0.017
18.59	11.60	0.017
18.64	11.55	0.017
18.70	11.49	0.017
18.76	11.44	0.017
18.81	11.38	0.017
18.87	11.33	0.017
18.92	11.27	0.017
18.98	11.22	0.017
19.03	11.16	0.017
19.08	11.11	0.017
19.14	11.05	0.017
19.19	11.00	0.017
19.25	10.94	0.017
19.31	10.89	0.017
19.36	10.83	0.017
19.42	10.78	0.017
19.47	10.72	0.017
19.53	10.67	0.017
19.58	10.61	0.017
19.63	10.56	0.017
19.69	10.50	0.017
19.74	10.45	0.017
19.80	10.39	0.017
19.86	10.34	0.017
19.91	10.28	0.017
19.97	10.23	0.017
20.02	10.17	0.017
20.08	10.12	0.017
20.13	10.06	0.017
20.18	10.01	0.017
20.24	9.95	0.017
20.29	9.90	0.017
20.35	9.84	0.017
20.41	9.79	0.017
20.46	9.73	0.017
20.52	9.68	0.017
20.57	9.62	0.017
20.63	9.57	0.017
20.68	9.51	0.017
20.73	9.46	0.017
20.79	9.40	0.017
20.84	9.35	0.017
20.90	9.29	0.017
20.96	9.24	0.017
21.01	9.18	0.017
21.07	9.13	0.017
21.12	9.07	0.017
21.18	9.02	0.017
21.23	8.96	0.017
21.28	8.91	0.017
21.34	8.85	0.017
21.39	8.80	0.017
21.45	8.74	0.017
21.51	8.69	0.017
21.56	8.63	0.017
21.62	8.58	0.017
21.67	8.52	0.017
21.73	8.47	0.017
21.78	8.41	0.017
21.83	8.36	0.017
21.89	8.30	0.017
21.94	8.25	0.017
22.00	8.19	0.017
22.06	8.14	0.017
22.11	8.08	0.017
22.17	8.03	0.017
22.22	7.97	0.017
22.28	7.92	0.017
22.33	7.86	0.017
22.38	7.81	0.017
22.44	7.75	0.017
22.49	7.70	0.017
22.55	7.64	0.017
22.61	7.59	0.017
22.66	7.53	0.017
22.72	7.48	0.017
22.77	7.42	0.017
22.83	7.37	0.017
22.88	7.31	0.017
22.93	7.26	0.017
22.99	7.20	0.017
23.04	7.15	0.017
23.10	7.09	0.017
23.16	7.04	0.017
23.21	6.98	0.017
23.27	6.93	0.017
23.32	6.87	0.017
23.38	6.82	0.017
23.43	6.76	0.017
23.48	6.71	0.017
23.54	6.65	0.017
23.59	6.60	0.017
23.65	6.54	0.017
23.71	6.49	0.017
23.76	6.43	0.017
23.82	6.38	0.017
23.87	6.32	0.017
23.93	6.27	0.017
23.98	6.21	0.017
24.03	6.16	0.017
24.09	6.10	0.017
24.14	6.05	0.017
24.20	5.99	0.017
24.26	5.94	0.017
24.31	5.89	0.017
24.37	5.83	0.017
24.42	5.77	0.017
24.48	5.72	0.017
24.53	5.66	0.017
24.58	5.61	0.017
24.64	5.55	0.017
24.69	5.50	0.017
24.75	5.44	0.017
24.81	5.39	0.017
24.86	5.33	0.017
24.92	5.28	0.017
24.97	5.22	0.017
25.03	5.17	0.017
25.08	5.11	0.017
25.13	5.06	0.017
25.19	5.00	0.017
25.24	4.95	0.017
25.30	4.89	0.017
25.36	4.84	0.017
25.41	4.78	0.017
25.47	4.73	0.017
25.52	4.68	0.017
25.58	4.62	0.017
25.63	4.57	0.017
25.68	4.51	0.017
25.74	4.46	0.017
25.79	4.40	0.017
25.85	4.35	0.017
25.91	4.29	0.017
25.96	4.24	0.017
26.02	4.18	0.017
26.07	4.12	0.017
26.13	4.07	0.017
26.18	4.02	0.017
26.23	3.96	0.017
26.29	3.90	0.017
26.34	3.85	0.017
26.40	3.80	0.017
26.46	3.74	0.017
26.51	3.69	0.017
26.57	3.63	0.017
26.62	3.58	0.017
26.68	3.52	0.017
26.73	3.47	0.017
26.78	3.41	0.017
26.84	3.36	0.017
26.89	3.30	0.017
26.95	3.25	0.017
27.01	3.19	0.017
27.06	3.14	0.017
27.12	3.08	0.017
27.17	3.02	0.017
27.23	2.97	0.017
27.28	2.92	0.017
27.33	2.86	0.017
27.39	2.81	0.017
27.44	2.75	0.017
27.50	2.69	0.017
27.56	2.64	0.017
27.61	2.59	0.017
27.67	2.53	0.017
27.72	2.47	0.017
27.78	2.42	0.017
27.83	2.37	0.017
27.88	2.31	0.017
27.94	2.26	0.017
27.99	2.20	0.017
28.05	2.15	0.017
28.11	2.09	0.017
28.16	2.04	0.017
28.22	1.98	0.017
28.27	1.93	0.017
28.33	1.87	0.017
28.38	1.82	0.017
28.43	1.76	0.017
28.49	1.71	0.017
28.54	1.65	0.017
28.60	1.60	0.017
28.66	1.54	0.017
28.71	1.49	0.017
28.77	1.43	0.017
28.82	1.38	0.017
28.88	1.32	0.017
28.93	1.27	0.017
28.98	1.21	0.017
29.04	1.16	0.017
29.09	1.10	0.017
29.15	1.05	0.017
29.21	0.99	0.017
29.26	0.94	0.017
29.32	0.88	0.017
29.37	0.83	0.017
29.43	0.77	0.017
29.48	0.72	0.017
29.53	0.66	0.017
29.59	0.61	0.017
29.64	0.55	0.017
29.70	0.50	0.017
29.76	0.44	0.017
29.81	0.39	0.017
29.87	0.33	0.017
29.92	0.28	0.017
29.98	0.22	0.017
30.03	0.17	0.017
30.08	0.11	0.017
30.14	0.06	0.017
30.19	0.00	0.017
30.25	-0.05	0.017
30.31	-0.11	0.017
30.36	-0.16	0.017
30.42	-0.22	0.017
30.47	-0.27	0.017
30.53	-0.33	0.017
30.58	-0.38	0.017
30.63	-0.44	0.017
30.69	-0.49	0.017
30.74	-0.55	0.017
30.80	-0.60	0.017
30.86	-0.66	0.017
30.91	-0.71	0.017
30.97	-0.77	0.017
31.02	-0.82	0.017
31.08	-0.88	0.017
31.13	-0.93	0.017
31.18	-0.99	0.017
31.24	-1.04	0.017
31.29	-1.10	0.017
31.35	-1.15	0.017
31.41	-1.21	0.017
31.46	-1.26	0.017
31.52	-1.32	0.017
31.57	-1.37	0.017
31.63	-1.43	0.017
31.68	-1.48	0.017
31.73	-1.54	0.017
31.79	-1.59	0.017
31.84	-1.65	0.017
31.90	-1.70	0.017
31.96	-1.76	0.017
32.01	-1.81	0.016
32.07	-1.87	0.016
32.12	-1.92	0.016
32.18	-1.98	0.016
32.23	-2.03	0.017
32.28	-2.09	0.017
32.34	-2.14	0.017
32.39	-2.20	0.016
32.45	-2.25	0.016
32.51	-2.31	0.016
32.56	-2.36	0.016
32.62	-2.42	0.016
32.67	-2.47	0.016
32.73	-2.53	0.017
32.78	-2.58	0.017
32.83	-2.64	0.017
32.89	-2.69	0.016
32.94	-2.75	0.016
33.00	-2.80	0.016
33.06	-2.86	0.017
33.11	-2.91	0.016
33.17	-2.97	0.016
33.22	-3.02	0.016
33.28	-3.08	0.016
33.33	-3.13	0.017
33.38	-3.19	0.017
33.44	-3.24	0.017
33.49	-3.30	0.017
33.55	-3.35	0.017
33.61	-3.41	0.017
33.66	-3.46	0.017
33.72	-3.52	0.017
33.77	-3.57	0.017
33.83	-3.63	0.017
33.88	-3.68	0.016
33.93	-3.74	0.016
33.99	-3.79	0.016
34.04	-3.85	0.016
34.10	-3.90	0.016
34.16	-3.96	0.016
34.21	-4.01	0.016
34.26	-4.07	0.016
34.32	-4.12	0.016
34.38	-4.18	0.016
34.43	-4.23	0.016
34.49	-4.29	0.016
34.54	-4.34	0.016
34.59	-4.40	0.016
34.65	-4.45	0.016
34.71	-4.51	0.016
34.76	-4.56	0.016
34.81	-4.62	0.016
34.87	-4.67	0.016
34.93	-4.73	0.016
34.98	-4.78	0.016
35.04	-4.84	0.016
35.09	-4.89	0.016
35.14	-4.95	0.016
35.20	-5.00	0.016
35.26	-5.06	0.016
35.31	-5.11	0.016
35.36	-5.17	0.016
35.42	-5.22	0.016
35.48	-5.28	0.016
35.53	-5.33	0.016
35.59	-5.39	0.016
35.64	-5.44	0.016
35.69	-5.50	0.016
35.75	-5.55	0.016
35.81	-5.61	0.016
35.86	-5.66	0.016
35.91	-5.72	0.016
35.97	-5.77	0.016
36.03	-5.83	0.016
36.08	-5.88	0.016
36.14	-5.94	0.016
36.19	-5.99	0.016
36.24	-6.05	0.016
36.30	-6.10	0.016
36.36	-6.16	0.016
36.41	-6.21	0.016
36.46	-6.27	0.016
36.52	-6.32	0.016
36.58	-6.38	0.016
36.63	-6.43	0.016
36.69	-6.49	0.016
36.74	-6.54	0.016
36.79	-6.60	0.016
36.85	-6.65	0.016
36.91	-6.71	0.016
36.96	-6.76	0.016
37.01	-6.82	0.016
37.07	-6.87	0.016
37.13	-6.93	0.016
37.18	-6.98	0.016
37.24	-7.04	0.016
37.29	-7.09	0.016
37.34	-7.15	0.016
37.40	-7.20	0.016
37.46	-7.25	0.016
37.51	-7.31	0.016
37.56	-7.37	0.016
37.62	-7.42	0.016
37.68	-7.48	0.016
37.73	-7.53	0.016
37.79	-7.58	0.016
37.84	-7.64	0.016
37.89	-7.70	0.016
37.95	-7.75	0.016
38.01	-7.80	0.016
38.06	-7.86	0.016
38.11	-7.92	0.016
38.17	-7.97	0.016
38.23	-8.03	0.016
38.28	-8.08	0.016
38.34	-8.14	0.016
38.39	-8.19	0.016
38.44	-8.25	0.016
38.50	-8.30	0.016
38.56	-8.36	0.016
38.61	-8.41	0.016
38.66	-8.47	0.016
38.72	-8.52	0.016
38.78	-8.58	0.016
38.83	-8.63	0.016
38.89	-8.69	0.016
38.94	-8.74	0.016
38.99	-8.80	0.016
39.05	-8.85	0.016
39.11	-8.91	0.016
39.16	-8.96	0.016
39.21	-9.02	0.016
39.27	-9.07	0.016
39.33	-9.12	0.016
39.38	-9.18	0.016
39.44	-9.24	0.016
39.49	-9.29	0.016
39.54	-9.35	0.016
39.60	-9.40	0.016
39.66	-9.46	0.016
39.71	-9.51	0.016
39.76	-9.57	0.016
39.82	-9.62	0.016
39.88	-9.68	0.016
39.93	-9.73	0.016
39.99	-9.79	0.016
40.04	-9.84	0.016
40.09	-9.90	0.016
40.15	-9.95	0.016
40.21	-10.00	0.016
40.26	-10.06	0.016
40.31	-10.12	0.016
40.37	-10.17	0.016
40.43	-10.22	0.016
40.48	-10.28	0.016
40.54	-10.34	0.016
40.59	-10.39	0.016
40.64	-10.44	0.016
40.70	-10.50	0.016
40.76	-10.55	0.016
40.81	-10.61	0.016
40.86	-10.66	0.016
40.92	-10.72	0.016
40.98	-10.78	0.016
41.03	-10.83	0.016
41.09	-10.89	0.016
41.14	-10.94	0.016
41.19	-10.99	0.016
41.25	-11.05	0.016
41.31	-11.10	0.016
41.36	-11.16	0.016
41.41	-11.21	0.016
41.47	-11.27	0.016
41.53	-11.32	0.016
41.58	-11.38	0.016
41.64	-11.43	0.016
41.69	-11.49	0.016
41.74	-11.54	0.016
41.80	-11.60	0.016
41.86	-11.65	0.016
41.91	-11.71	0.016
41.96	-11.76	0.016
42.02	-11.82	0.016
42.08	-11.87	0.016
42.13	-11.93	0.016
42.19	-11.98	0.016
42.24	-12.04	0.016
42.29	-12.09	0.016
42.35	-12.15	0.016
42.41	-12.20	0.016
42.46	-12.26	0.016
42.51	-12.31	0.016
42.57	-12.37	0.016
42.63	-12.42	0.016
42.68	-12.48	0.016
42.74	-12.53	0.016
42.79	-12.59	0.016
42.84	-12.64	0.016
42.90	-12.70	0.016
42.96	-12.76	0.016
43.01	-12.81	0.016
43.06	-12.87	0.016
43.12	-12.92	0.016
43.18	-12.97	0.016
43.23	-13.03	0.016
43.29	-13.08	0.016
43.34	-13.14	0.016
43.39	-13.19	0.016
43.45	-13.25	0.016
43.51	-13.30	0.016
43.56	-13.36	0.016
43.61	-13.41	0.016
43.67	-13.47	0.016
43.73	-13.52	0.016
43.78	-13.58	0.016
43.84	-13.63	0.016
43.89	-13.69	0.016
43.94	-13.74	0.016
44.00	-13.80	0.016
44.06	-13.85	0.016
44.11	-13.91	0.016
44.16	-13.96	0.016
44.22	-14.02	0.016
44.28	-14.07	0.016
44.33	-14.13	0.016
44.39	-14.18	0.016
44.44	-14.24	0.016
44.49	-14.29	0.016
44.55	-14.35	0.016
44.61	-14.40	0.016
44.66	-14.46	0.016
44.71	-14.51	0.016
44.77	-14.57	0.016
44.83	-14.62	0.016
44.88	-14.68	0.016
44.94	-14.73	0.016
44.99	-14.79	0.016
45.04	-14.84	0.016
45.10	-14.90	0.016
45.16	-14.95	0.016
45.21	-15.01	0.016
45.26	-15.06	0.016
45.32	-15.12	0.016
45.38	-15.17	0.016
45.43	-15.23	0.016
45.49	-15.28	0.016
45.54	-15.34	0.016
45.59	-15.39	0.016
45.65	-15.45	0.016
45.71	-15.50	0.016
45.76	-15.56	0.016
45.81	-15.61	0.016
45.87	-15.67	0.016
45.93	-15.72	0.016
45.98	-15.78	0.016
46.04	-15.83	0.016
46.09	-15.89	0.016
46.14	-15.94	0.016
46.20	-16.00	0.016
46.26	-16.05	0.016
46.31	-16.11	0.016
46.36	-16.16	0.016
46.42	-16.22	0.016
46.48	-16.27	0.016
46.53	-16.33	0.016
46.59	-16.38	0.016
46.64	-16.44	0.016
46.69	-16.49	0.016
46.75	-16.55	0.016
46.81	-16.60	0.016
46.86	-16.66	0.016
46.91	-16.71	0.016
46.97	-16.77	0.016
47.03	-16.82	0.016
47.08	-16.88	0.016
47.14	-16.93	0.016
47.19	-16.99	0.016
47.24	-17.04	0.016
47.30	-17.10	0.016
47.36	-17.15	0.016
47.41	-17.21	0.016
47.46	-17.26	0.016
47.52	-17.32	0.016
47.58	-17.37	0.016
47.63	-17.43	0.016
47.69	-17.48	0.016
47.74	-17.54	0.016
47.79	-17.59	0.016
47.85	-17.65	0.016
47.91	-17.70	0.016
47.96	-17.76	0.016
48.01	-17.81	0.016
48.07	-17.87	0.016
48.13	-17.92	0.016
48.18	-17.98	0.016
48.24	-18.03	0.016
48.29	-18.09	0.016
48.34	-18.14	0.016
48.40	-18.20	0.016
48.46	-18.25	0.016
48.51	-18.31	0.016
48.56	-18.36	0.016
48.62	-18.42	0.016
48.68	-18.47	0.016
48.73	-18.53	0.016
48.79	-18.58	0.016
48.84	-18.64	0.016
48.89	-18.69	0.016
48.95	-18.75	0.016
49.01	-18.80	0.016
49.06	-18.86	0.016
49.11	-18.91	0.016
49.17	-18.97	0.016
49.23	-19.02	0.016
49.28	-19.08	0.016
49.34	-19.13	0.016
49.39	-19.19	0.016
49.44	-19.24	0.016
49.50	-19.30	0.016
49.56	-19.35	0.016
49.61	-19.41	0.016
49.66	-19.46	0.016
49.72	-19.52	0.016
49.78	-19.57	0.016
49.83	-19.63	0.016
49.89	-19.68	0.016
49.94	-19.74	0.016
49.99	-19.79	0.016
50.05	-19.85	0.016
50.11	-19.90	0.016
50.16	-19.96	0.016
50.21	-20.01	0.016
50.27	-20.07	0.016
50.33	-20.12	0.016
50.38	-20.18	0.016
50.44	-20.23	0.016
50.49	-20.29	0.016
50.54	-20.34	0.016
50.60	-20.40	0.016
50.66	-20.45	0.016
50.71	-20.51	0.016
50.76	-20.56	0.016
50.82	-20.62	0.016
50.88	-20.67	0.016
50.93	-20.73	0.016
50.99	-20.78	0.016
51.04	-20.84	0.016
51.09	-20.89	0.016
51.15	-20.95	0.016
51.21	-21.00	0.016
51.26	-21.06	0.016
51.31	-21.11	0.016
51.37	-21.17	0.016
51.43	-21.22	0.016
51.48	-21.28	0.016
51.54	-21.33	0.016
51.59	-21.39	0.016
51.64	-21.44	0.016
51.70	-21.50	0.016
51.76	-21.55	0.016
51.81	-21.61	0.016
51.86	-21.66	0.016
51.92	-21.72	0.016
51.98	-21.77	0.016
52.03	-21.83	0.016
52.09	-21.88	0.016
52.14	-21.94	0.016
52.19	-21.99	0.016
52.25	-22.05	0.016
52.31	-22.10	0.016
52.36	-22.16	0.016
52.41	-22.21	0.016
52.47	-22.27	0.016
52.53	-22.32	0.016
52.58	-22.38	0.016
52.64	-22.43	0.016
52.69	-22.49	0.016
52.74	-22.54	0.016
52.80	-22.60	0.016
52.86	-22.65	0.016
52.91	-22.71	0.016
52.96	-22.76	0.016
53.02	-22.82	0.016
53.08	-22.87	0.016
53.13	-22.93	0.016
53.19	-22.98	0.016
53.24	-23.04	0.016
53.29	-23.09	0.016
53.35	-23.14	0.016
53.41	-23.20	0.016
53.46	-23.26	0.016
53.51	-23.31	0.016
53.57	-23.37	0.016
53.63	-23.42	0.016
53.68	-23.48	0.016
53.74	-23.53	0.016
53.79	-23.59	0.016
53.84	-23.64	0.016
53.90	-23.70	0.016
53.96	-23.75	0.016
54.01	-23.81	0.016
54.06	-23.86	0.016
54.12	-23.92	0.016
54.18	-23.97	0.016
54.23	-24.03	0.016
54.29	-24.08	0.016
54.34	-24.14	0.016
54.39	-24.19	0.016
54.45	-24.25	0.016
54.51	-24.30	0.016
54.56	-24.36	0.016
54.61	-24.41	0.016
54.67	-24.47	0.016
54.73	-24.52	0.016
54.78	-24.58	0.016
54.84	-24.63	0.016
54.89	-24.69	0.016
54.94	-24.74	0.016
55.00	-24.80	0.016
55.06	-24.85	0.016
55.11	-24.91	0.016
55.16	-24.96	0.016
55.22	-25.02	0.016
55.28	-25.07	0.016
55.33	-25.13	0.016
55.39	-25.18	0.016
55.44	-25.24	0.016
55.49	-25.29	0.016
55.55	-25.35	0.016
55.61	-25.40	0.016
55.66	-25.46	0.016
55.71	-25.51	0.016
55.77	-25.57	0.016
55.83	-25.62	0.016
55.88	-25.68	0.016
55.94	-25.73	0.016
55.99	-25.79	0.016
56.04	-25.84	0.016
56.10	-25.89	0.016
56.16	-25.95	0.016
56.21	-26.01	0.016
56.26	-26.06	0.016
56.32	-26.12	0.016
56.38	-26.17	0.016
56.43	-26.23	0.016
56.49	-26.28	0.016
56.54	-26.34	0.016
56.59	-26.39	0.016
56.65	-26.45	0.016
56.71	-26.50	0.015
56.76	-26.56	0.015
56.81	-26.61	0.015
56.87	-26.67	0.015
56.93	-26.72	0.015
56.98	-26.78	0.015
57.04	-26.83	0.015
57.09	-26.89	0.015
57.14	-26.94	0.015
57.20	-27.00	0.015
57.26	-27.05	0.015
57.31	-27.11	0.015
57.36	-27.16	0.015
57.42	-27.22	0.015
57.48	-27.27	0.015
57.53	-27.33	0.015
57.59	-27.38	0.015
57.64	-27.44	0.015
57.69	-27.49	0.015
57.75	-27.55	0.015
57.81	-27.60	0.015
57.86	-27.66	0.015
57.91	-27.71	0.015
57.97	-27.77	0.015
58.03	-27.82	0.015
58.08	-27.88	0.015
58.14	-27.93	0.015
58.19	-27.99	0.015
58.24	-28.04	0.015
58.30	-28.10	0.015
58.36	-28.15	0.015
58.41	-28.21	0.015
58.46	-28.26	0.015
58.52	-28.32	0.015
58.58	-28.37	0.015
58.63	-28.43	0.015
58.69	-28.48	0.015
58.74	-28.54	0.015
58.79	-28.59	0.015
58.85	-28.65	0.015
58.91	-28.70	0.015
58.96	-28.76	0.015
59.01	-28.81	0.015
59.07	-28.87	0.015
59.13	-28.92	0.015
59.18	-28.98	0.015
59.24	-29.03	0.015
59.29	-29.08	0.015
59.34	-29.14	0.015
59.40	-29.19	0.015
59.46	-29.25	0.015
59.51	-29.30	0.015
59.56	-29.36	0.015
59.62	-29.41	0.015
59.68	-29.47	0.015
59.73	-29.53	0.015
59.79	-29.58	0.015
59.84	-29.64	0.015
59.89	-29.69	0.015
59.95	-29.75	0.015
60.01	-29.80	0.015
60.06	-29.86	0.015
60.11	-29.91	0.015
60.17	-29.97	0.015
60.23	-30.02	0.015
60.28	-30.08	0.015
60.34	-30.13	0.015
60.39	-30.19	0.015
60.44	-30.24	0.015
60.50	-30.30	0.015
60.56	-30.35	0.015
60.61	-30.41	0.015
60.66	-30.46	0.015
60.72	-30.52	0.015
60.78	-30.57	0.015
60.83	-30.63	0.015
60.89	-30.68	0.015
60.94	-30.74	0.015
60.99	-30.79	0.015
61.05	-30.85	0.015
61.11	-30.90	0.015
61.16	-30.96	0.015
61.21	-31.01	0.015
61.27	-31.07	0.015
61.33	-31.12	0.015
61.38	-31.18	0.015
61.44	-31.23	0.015
61.49	-31.29	0.015
61.54	-31.34	0.015
61.60	-31.40	0.015
61.66	-31.45	0.015
61.71	-31.51	0.015
61.76	-31.56	0.015
61.82	-31.62	0.015
61.88	-31.67	0.015
61.93	-31.73	0.015
61.99	-31.78	0.015
62.04	-31.84	0.015
62.09	-31.89	0.015
62.15	-31.94	0.015
62.21	-32.00	0.015
62.26	-32.06	0.015
62.31	-32.11	0.015
62.37	-32.17	0.015
62.43	-32.22	0.015
62.48	-32.27	0.015
62.54	-32.33	0.015
62.59	-32.38	0.015
62.64	-32.44	0.015
62.70	-32.50	0.015
62.76	-32.55	0.015
62.81	-32.61	0.015
62.86	-32.66	0.015
62.92	-32.72	0.015
62.98	-32.77	0.015
63.03	-32.83	0.015
63.09	-32.88	0.015
63.14	-32.94	0.015
63.19	-32.99	0.015
63.25	-33.05	0.015
63.31	-33.10	0.015
63.36	-33.15	0.015
63.41	-33.21	0.015
63.47	-33.27	0.015
63.53	-33.32	0.015
63.58	-33.38	0.015
63.64	-33.43	0.015
63.69	-33.48	0.015
63.74	-33.54	0.015
63.80	-33.60	0.015
63.86	-33.65	0.015
63.91	-33.70	0.015
63.96	-33.76	0.015
64.02	-33.81	0.015
64.08	-33.87	0.015
64.13	-33.93	0.015
64.19	-33.98	0.015
64.24	-34.03	0.015
64.29	-34.09	0.015
64.35	-34.15	0.015
64.41	-34.20	0.015
64.46	-34.25	0.015
64.51	-34.31	0.015
64.57	-34.36	0.015
64.63	-34.42	0.015
64.68	-34.47	0.015
64.74	-34.53	0.015
64.79	-34.58	0.015
64.84	-34.64	0.015
64.90	-34.69	0.015
64.96	-34.75	0.015
65.01	-34.80	0.015
65.06	-34.86	0.015
65.12	-34.91	0.015
65.18	-34.97	0.015
65.23	-35.02	0.015
65.29	-35.08	0.015
65.34	-35.13	0.015
65.39	-35.19	0.015
65.45	-35.24	0.015
65.51	-35.30	0.015
65.56	-35.35	0.015
65.61	-35.41	0.015
65.67	-35.46	0.015
65.73	-35.52	0.015
65.78	-35.57	0.015
65.84	-35.63	0.015
65.89	-35.68	0.015
65.94	-35.74	0.015
66.00	-35.80	0.015
66.06	-35.85	0.015
66.11	-35.90	0.015
66.16	-35.96	0.015
66.22	-36.01	0.015
66.28	-36.07	0.015
66.33	-36.12	0.015
66.39	-36.18	0.015
66.44	-36.23	0.015
66.49	-36.29	0.015
66.55	-36.34	0.015
66.61	-36.40	0.015
66.66	-36.45	0.015
66.71	-36.51	0.015
66.77	-36.57	0.015
66.83	-36.62	0.015
66.88	-36.67	0.015
66.94	-36.73	0.015
66.99	-36.78	0.015
67.04	-36.84	0.015
67.10	-36.89	0.015
67.16	-36.95	0.015
67.21	-37.00	0.015
67.26	-37.06	0.015
67.32	-37.11	0.015
67.38	-37.17	0.015
67.43	-37.22	0.015
67.49	-37.28	0.015
67.54	-37.33	0.015
67.59	-37.39	0.015
67.65	-37.44	0.015
67.71	-37.50	0.015
67.76	-37.55	0.015
67.81	-37.61	0.015
67.87	-37.66	0.015
67.93	-37.72	0.015
67.98	-37.77	0.015
68.04	-37.83	0.015
68.09	-37.88	0.015
68.14	-37.94	0.015
68.20	-37.99	0.015
68.26	-38.05	0.015
68.31	-38.10	0.015
68.36	-38.16	0.015
68.42	-38.21	0.015
68.48	-38.27	0.015
68.53	-38.32	0.015
68.59	-38.38	0.015
68.64	-38.43	0.015
68.70	-38.49	0.015
68.75	-38.54	0.015
68.80	-38.60	0.015
68.86	-38.65	0.015
68.91	-38.71	0.015
68.97	-38.76	0.015
69.03	-38.82	0.015
69.08	-38.87	0.015
69.14	-38.93	0.015
69.19	-38.98	0.015
69.25	-39.04	0.015
69.30	-39.09	0.015
69.35	-39.15	0.015
69.41	-39.20	0.015
69.46	-39.26	0.015
69.52	-39.31	0.015
69.58	-39.37	0.015
69.63	-39.42	0.015
69.69	-39.48	0.015
69.74	-39.53	0.015
69.80	-39.59	0.015
69.85	-39.64	0.015
69.90	-39.70	0.015
69.96	-39.75	0.015
70.01	-39.81	0.015
70.07	-39.86	0.015
70.13	-39.92	0.015
70.18	-39.97	0.015
70.24	-40.03	0.015
70.29	-40.08	0.015
70.35	-40.14	0.015
70.40	-40.19	0.015
70.45	-40.25	0.015
70.51	-40.30	0.015
70.56	-40.36	0.015
70.62	-40.41	0.015
70.68	-40.47	0.015
70.73	-40.52	0.015
70.79	-40.58	0.015
70.84	-40.63	0.015
70.90	-40.69	0.015
70.95	-40.74	0.015
71.00	-40.80	0.015
71.06	-40.85	0.015
71.11	-40.91	0.015
71.17	-40.96	0.015
71.23	-41.02	0.015
71.28	-41.07	0.015
71.34	-41.13	0.015
71.39	-41.18	0.015
71.45	-41.24	0.015
71.50	-41.29	0.015
71.55	-41.35	0.015
71.61	-41.40	0.015
71.66	-41.46	0.015
71.72	-41.51	0.015
71.78	-41.57	0.015
71.83	-41.62	0.015
71.89	-41.68	0.015
71.94	-41.73	0.015
72.00	-41.79	0.015
72.05	-41.84	0.015
72.10	-41.90	0.015
72.16	-41.95	0.015
72.21	-42.01	0.015
72.27	-42.06	0.015
72.33	-42.12	0.015
72.38	-42.17	0.015
72.44	-42.23	0.015
72.49	-42.28	0.015
72.55	-42.34	0.015
72.60	-42.39	0.015
72.65	-42.45	0.015
72.71	-42.50	0.015
72.76	-42.56	0.015
72.82	-42.61	0.015
72.88	-42.67	0.015
72.93	-42.72	0.015
72.99	-42.78	0.015
73.04	-42.83	0.015
73.10	-42.89	0.015
73.15	-42.94	0.015
73.20	-43.00	0.015
73.26	-43.05	0.015
73.31	-43.11	0.015
73.37	-43.16	0.015
73.43	-43.22	0.015
73.48	-43.27	0.015
73.54	-43.33	0.015
73.59	-43.38	0.015
73.65	-43.44	0.015
73.70	-43.49	0.015
73.75	-43.55	0.015
73.81	-43.60	0.015
73.86	-43.66	0.015
73.92	-43.71	0.015
73.98	-43.77	0.015
74.03	-43.82	0.015
74.09	-43.88	0.015
74.14	-43.93	0.015
74.20	-43.99	0.015
74.25	-44.04	0.015
74.30	-44.10	0.015
74.36	-44.15	0.015
74.41	-44.21	0.015
74.47	-44.26	0.015
74.53	-44.32	0.015
74.58	-44.37	0.015
74.64	-44.43	0.015
74.69	-44.48	0.015
74.75	-44.54	0.015
74.80	-44.59	0.015
74.85	-44.65	0.015
74.91	-44.70	0.015
74.96	-44.76	0.015
75.02	-44.81	0.015
75.08	-44.87	0.015
75.13	-44.92	0.015
75.19	-44.98	0.015
75.24	-45.03	0.015
75.30	-45.09	0.015
75.35	-45.14	0.015
75.40	-45.20	0.015
75.46	-45.25	0.015
75.51	-45.31	0.015
75.57	-45.36	0.015
75.63	-45.42	0.015
75.68	-45.47	0.015
75.74	-45.53	0.015
75.79	-45.58	0.015
75.85	-45.64	0.015
75.90	-45.69	0.015
75.95	-45.75	0.015
76.01	-45.80	0.015
76.06	-45.85	0.015
76.12	-45.91	0.015
76.18	-45.97	0.015
76.23	-46.02	0.015
76.29	-46.08	0.015
76.34	-46.13	0.015
76.40	-46.19	0.015
76.45	-46.24	0.015
76.50	-46.30	0.015
76.56	-46.35	0.015
76.61	-46.40	0.015
76.67	-46.46	0.015
76.73	-46.52	0.015
76.78	-46.57	0.015
76.84	-46.63	0.015
76.89	-46.68	0.015
76.95	-46.74	0.015
77.00	-46.79	0.015
77.05	-46.85	0.015
77.11	-46.90	0.015
77.16	-46.96	0.015
77.22	-47.01	0.015
77.28	-47.07	0.015
77.33	-47.12	0.015
77.39	-47.17	0.015
77.44	-47.23	0.015
77.50	-47.28	0.015
77.55	-47.34	0.016
77.60	-47.39	0.016
77.66	-47.45	0.017
77.71	-47.50	0.018
77.77	-47.55	0.019
77.83	-47.61	0.022
77.88	-47.66	0.026
77.94	-47.71	0.030
77.99	-47.77	0.034
78.05	-47.82	0.039
78.10	-47.87	0.044
78.15	-47.92	0.050
78.21	-47.98	0.056
78.26	-48.03	0.063
78.32	-48.08	0.071
78.38	-48.13	0.079
78.43	-48.18	0.089
78.49	-48.23	0.100
78.54	-48.28	0.112
78.60	-48.32	0.124
78.65	-48.37	0.136
78.70	-48.42	0.149
78.76	-48.47	0.162
78.81	-48.52	0.175
78.87	-48.56	0.190
78.93	-48.61	0.202
78.98	-48.66	0.211
79.04	-48.71	0.218
79.09	-48.77	0.223
79.15	-48.82	0.227
79.20	-48.87	0.232
79.25	-48.92	0.239
79.31	-48.97	0.246
79.36	-49.02	0.253
79.42	-49.07	0.261
79.48	-49.12	0.270
79.53	-49.17	0.278
79.59	-49.22	0.287
79.64	-49.27	0.295
79.70	-49.32	0.303
79.75	-49.38	0.311
79.80	-49.43	0.318
79.86	-49.48	0.324
79.91	-49.53	0.330
79.97	-49.58	0.336
80.00	-49.61	0.339

[step]
Isothermal 60.0 min
Time	Temperature	Heat Flow (Normalized)
min	°C	W/g
80.00	-49.61	0.339
80.04	-49.65	0.343
80.08	-49.68	0.346
80.12	-49.70	0.347
80.16	-49.71	0.347
80.20	-49.71	0.347
80.24	-49.72	0.345
80.28	-49.73	0.339
80.32	-49.73	0.333
80.36	-49.73	0.326
80.40	-49.74	0.320
80.44	-49.74	0.314
80.48	-49.75	0.307
80.52	-49.75	0.300
80.56	-49.75	0.295
80.60	-49.76	0.290
80.64	-49.76	0.285
80.68	-49.76	0.280
80.72	-49.77	0.274
80.76	-49.77	0.268
80.80	-49.78	0.262
80.84	-49.78	0.258
80.88	-49.78	0.254
80.92	-49.78	0.251
80.96	-49.78	0.249
81.00	-49.78	0.248
81.04	-49.79	0.247
81.08	-49.79	0.246
81.12	-49.79	0.246
81.16	-49.79	0.245
81.20	-49.79	0.245
81.24	-49.79	0.245
81.28	-49.79	0.244
81.32	-49.79	0.244
81.36	-49.79	0.237
81.40	-49.80	0.224
81.44	-49.80	0.212
81.48	-49.81	0.200
81.52	-49.82	0.189
81.56	-49.82	0.179
81.60	-49.83	0.171
81.64	-49.83	0.163
81.68	-49.84	0.156
81.72	-49.84	0.150
81.76	-49.84	0.144
81.80	-49.85	0.139
81.84	-49.85	0.135
81.88	-49.85	0.130
81.92	-49.85	0.126
81.96	-49.86	0.123
82.00	-49.86	0.119
82.04	-49.86	0.116
82.08	-49.86	0.113
82.12	-49.86	0.107
82.16	-49.87	0.100
82.20	-49.87	0.091
82.24	-49.88	0.082
82.28	-49.88	0.073
82.32	-49.89	0.064
82.36	-49.89	0.054
82.40	-49.90	0.045
82.44	-49.90	0.036
82.48	-49.91	0.027
82.52	-49.91	0.021
82.56	-49.92	0.015
82.60	-49.92	0.011
82.64	-49.92	0.008
82.68	-49.92	0.006
82.72	-49.92	0.004
82.76	-49.92	0.003
82.80	-49.92	0.003
82.84	-49.92	0.002
82.88	-49.92	0.001
82.92	-49.92	0.001
82.96	-49.92	0.000
83.00	-49.93	0.000
83.04	-49.93	-0.001
83.08	-49.93	-0.002
83.12	-49.93	-0.002
83.16	-49.93	-0.003
83.20	-49.93	-0.003
83.24	-49.93	-0.004
83.28	-49.93	-0.004
83.32	-49.93	-0.004
83.36	-49.93	-0.005
83.40	-49.93	-0.005
83.44	-49.93	-0.006
83.48	-49.93	-0.006
83.52	-49.93	-0.006
83.56	-49.93	-0.007
83.60	-49.93	-0.007
83.64	-49.93	-0.007
83.68	-49.93	-0.008
83.72	-49.93	-0.008
83.76	-49.93	-0.008
83.80	-49.93	-0.008
83.84	-49.93	-0.009
83.88	-49.93	-0.009
83.92	-49.93	-0.009
83.96	-49.93	-0.009
84.00	-49.93	-0.009
84.04	-49.93	-0.010
84.08	-49.93	-0.010
84.12	-49.93	-0.010
84.16	-49.93	-0.010
84.20	-49.93	-0.010
84.24	-49.93	-0.010
84.28	-49.93	-0.011
84.32	-49.93	-0.011
84.36	-49.93	-0.011
84.40	-49.93	-0.011
84.44	-49.93	-0.011
84.48	-49.93	-0.011
84.52	-49.93	-0.012
84.56	-49.93	-0.012
84.60	-49.93	-0.012
84.64	-49.93	-0.012
84.68	-49.93	-0.012
84.72	-49.93	-0.012
84.76	-49.93	-0.012
84.80	-49.93	-0.013
84.84	-49.93	-0.013
84.88	-49.93	-0.013
84.92	-49.93	-0.013
84.96	-49.93	-0.013
85.00	-49.93	-0.013
85.04	-49.93	-0.013
85.08	-49.93	-0.013
85.12	-49.93	-0.013
85.16	-49.93	-0.013
85.20	-49.93	-0.013
85.24	-49.93	-0.013
85.28	-49.93	-0.013
85.32	-49.93	-0.013
85.36	-49.93	-0.014
85.40	-49.93	-0.014
85.44	-49.93	-0.014
85.48	-49.93	-0.014
85.52	-49.93	-0.014
85.56	-49.93	-0.014
85.60	-49.93	-0.014
85.64	-49.93	-0.014
85.68	-49.93	-0.014
85.72	-49.93	-0.014
85.76	-49.93	-0.014
85.80	-49.93	-0.014
85.84	-49.93	-0.014
85.88	-49.93	-0.014
85.92	-49.93	-0.014
85.96	-49.93	-0.014
86.00	-49.93	-0.014
86.04	-49.93	-0.014
86.08	-49.93	-0.014
86.12	-49.93	-0.014
86.16	-49.93	-0.014
86.20	-49.93	-0.014
86.24	-49.93	-0.014
86.28	-49.93	-0.014
86.32	-49.93	-0.015
86.36	-49.93	-0.015
86.40	-49.93	-0.015
86.44	-49.93	-0.015
86.48	-49.93	-0.015
86.52	-49.93	-0.015
86.56	-49.93	-0.015
86.60	-49.93	-0.015
86.64	-49.93	-0.015
86.68	-49.93	-0.015
86.72	-49.93	-0.015
86.76	-49.93	-0.015
86.80	-49.93	-0.015
86.84	-49.93	-0.015
86.88	-49.93	-0.015
86.92	-49.93	-0.015
86.96	-49.93	-0.015
87.00	-49.93	-0.015
87.04	-49.93	-0.015
87.08	-49.93	-0.015
87.12	-49.93	-0.015
87.16	-49.93	-0.015
87.20	-49.93	-0.015
87.24	-49.93	-0.015
87.28	-49.93	-0.015
87.32	-49.93	-0.015
87.36	-49.93	-0.015
87.40	-49.93	-0.015
87.44	-49.93	-0.015
87.48	-49.93	-0.015
87.52	-49.93	-0.015
87.56	-49.93	-0.015
87.60	-49.93	-0.015
87.64	-49.93	-0.015
87.68	-49.93	-0.015
87.72	-49.93	-0.015
87.76	-49.93	-0.015
87.80	-49.93	-0.015
87.84	-49.93	-0.015
87.88	-49.93	-0.015
87.92	-49.93	-0.015
87.96	-49.93	-0.015
88.00	-49.93	-0.015
88.04	-49.93	-0.015
88.08	-49.93	-0.016
88.12	-49.93	-0.016
88.16	-49.93	-0.016
88.20	-49.93	-0.016
88.24	-49.93	-0.016
88.28	-49.93	-0.016
88.32	-49.93	-0.016
88.36	-49.93	-0.016
88.40	-49.93	-0.016
88.44	-49.93	-0.016
88.48	-49.93	-0.016
88.52	-49.93	-0.016
88.56	-49.93	-0.016
88.60	-49.93	-0.016
88.64	-49.93	-0.016
88.68	-49.93	-0.016
88.72	-49.93	-0.016
88.76	-49.93	-0.016
88.80	-49.93	-0.016
88.84	-49.93	-0.016
88.88	-49.93	-0.016
88.92	-49.93	-0.016
88.96	-49.93	-0.016
89.00	-49.93	-0.016
89.04	-49.93	-0.016
89.08	-49.93	-0.016
89.12	-49.93	-0.016
89.16	-49.93	-0.016
89.20	-49.93	-0.016
89.24	-49.93	-0.016
89.28	-49.93	-0.016
89.32	-49.93	-0.016
89.36	-49.93	-0.016
89.40	-49.93	-0.016
89.44	-49.93	-0.016
89.48	-49.93	-0.016
89.52	-49.93	-0.016
89.56	-49.93	-0.016
89.60	-49.93	-0.016
89.64	-49.93	-0.016
89.68	-49.93	-0.016
89.72	-49.93	-0.016
89.76	-49.93	-0.016
89.80	-49.93	-0.016
89.84	-49.93	-0.016
89.88	-49.93	-0.016
89.92	-49.93	-0.016
89.96	-49.93	-0.016
90.00	-49.93	-0.016
90.04	-49.93	-0.016
90.08	-49.93	-0.016
90.12	-49.93	-0.016
90.16	-49.93	-0.016
90.20	-49.93	-0.016
90.24	-49.93	-0.016
90.28	-49.93	-0.016
90.32	-49.93	-0.016
90.36	-49.93	-0.016
90.40	-49.93	-0.016
90.44	-49.93	-0.016
90.48	-49.93	-0.016
90.52	-49.93	-0.016
90.56	-49.93	-0.016
90.60	-49.93	-0.016
90.64	-49.93	-0.016
90.68	-49.93	-0.016
90.72	-49.93	-0.016
90.76	-49.93	-0.016
90.80	-49.93	-0.016
90.84	-49.93	-0.016
90.88	-49.93	-0.016
90.92	-49.93	-0.016
90.96	-49.93	-0.016
91.00	-49.93	-0.016
91.04	-49.93	-0.016
91.08	-49.93	-0.016
91.12	-49.93	-0.016
91.16	-49.93	-0.016
91.20	-49.93	-0.016
91.24	-49.93	-0.016
91.28	-49.93	-0.016
91.32	-49.93	-0.016
91.36	-49.93	-0.016
91.40	-49.93	-0.016
91.44	-49.93	-0.016
91.48	-49.93	-0.016
91.52	-49.93	-0.016
91.56	-49.93	-0.016
91.60	-49.93	-0.016
91.64	-49.93	-0.016
91.68	-49.93	-0.016
91.72	-49.93	-0.016
91.76	-49.93	-0.016
91.80	-49.93	-0.016
91.84	-49.93	-0.016
91.88	-49.93	-0.016
91.92	-49.93	-0.016
91.96	-49.93	-0.016
92.00	-49.93	-0.016
92.04	-49.93	-0.016
92.08	-49.93	-0.016
92.12	-49.93	-0.016
92.16	-49.93	-0.016
92.20	-49.93	-0.016
92.24	-49.93	-0.016
92.28	-49.93	-0.016
92.32	-49.93	-0.016
92.36	-49.93	-0.016
92.40	-49.93	-0.016
92.44	-49.93	-0.016
92.48	-49.93	-0.016
92.52	-49.93	-0.016
92.56	-49.93	-0.016
92.60	-49.93	-0.016
92.64	-49.93	-0.016
92.68	-49.93	-0.016
92.72	-49.93	-0.016
92.76	-49.93	-0.016
92.80	-49.93	-0.016
92.84	-49.93	-0.016
92.88	-49.93	-0.016
92.92	-49.93	-0.016
92.96	-49.93	-0.016
93.00	-49.93	-0.016
93.04	-49.93	-0.017
93.08	-49.93	-0.017
93.12	-49.93	-0.017
93.16	-49.93	-0.017
93.20	-49.93	-0.017
93.24	-49.93	-0.017
93.28	-49.93	-0.017
93.32	-49.93	-0.017
93.36	-49.93	-0.017
93.40	-49.93	-0.017
93.44	-49.93	-0.017
93.48	-49.93	-0.017
93.52	-49.93	-0.017
93.56	-49.93	-0.017
93.60	-49.93	-0.017
93.64	-49.93	-0.017
93.68	-49.93	-0.016
93.72	-49.93	-0.016
93.76	-49.93	-0.016
93.80	-49.93	-0.016
93.84	-49.93	-0.016
93.88	-49.93	-0.017
93.92	-49.93	-0.017
93.96	-49.93	-0.017
94.00	-49.93	-0.017
94.04	-49.93	-0.017
94.08	-49.93	-0.017
94.12	-49.93	-0.017
94.16	-49.93	-0.017
94.20	-49.93	-0.017
94.24	-49.93	-0.017
94.28	-49.93	-0.017
94.32	-49.93	-0.017
94.36	-49.93	-0.017
94.40	-49.93	-0.017
94.44	-49.93	-0.017
94.48	-49.93	-0.017
94.52	-49.93	-0.017
94.56	-49.93	-0.017
94.60	-49.93	-0.017
94.64	-49.93	-0.017
94.68	-49.93	-0.017
94.72	-49.93	-0.017
94.76	-49.93	-0.017
94.80	-49.93	-0.017
94.84	-49.93	-0.017
94.88	-49.93	-0.017
94.92	-49.93	-0.017
94.96	-49.93	-0.017
95.00	-49.93	-0.017
95.04	-49.93	-0.017
95.08	-49.93	-0.017
95.12	-49.93	-0.017
95.16	-49.93	-0.017
95.20	-49.93	-0.017
95.24	-49.93	-0.017
95.28	-49.93	-0.017
95.32	-49.93	-0.017
95.36	-49.93	-0.017
95.40	-49.93	-0.017
95.44	-49.93	-0.017
95.48	-49.93	-0.017
95.52	-49.93	-0.017
95.56	-49.93	-0.017
95.60	-49.93	-0.017
95.64	-49.93	-0.017
95.68	-49.93	-0.017
95.72	-49.93	-0.017
95.76	-49.93	-0.017
95.80	-49.93	-0.017
95.84	-49.93	-0.017
95.88	-49.93	-0.017
95.92	-49.93	-0.017
95.96	-49.93	-0.017
96.00	-49.93	-0.017
96.04	-49.93	-0.017
96.08	-49.93	-0.017
96.12	-49.93	-0.017
96.16	-49.93	-0.017
96.20	-49.93	-0.017
96.24	-49.93	-0.017
96.28	-49.93	-0.017
96.32	-49.93	-0.017
96.36	-49.93	-0.017
96.40	-49.93	-0.017
96.44	-49.93	-0.017
96.48	-49.93	-0.017
96.52	-49.93	-0.017
96.56	-49.93	-0.017
96.60	-49.93	-0.017
96.64	-49.93	-0.017
96.68	-49.93	-0.017
96.72	-49.93	-0.017
96.76	-49.93	-0.017
96.80	-49.93	-0.017
96.84	-49.93	-0.017
96.88	-49.93	-0.017
96.92	-49.93	-0.017
96.96	-49.93	-0.017
97.00	-49.93	-0.017
97.04	-49.93	-0.017
97.08	-49.93	-0.017
97.12	-49.93	-0.017
97.16	-49.93	-0.017
97.20	-49.93	-0.017
97.24	-49.93	-0.017
97.28	-49.93	-0.017
97.32	-49.93	-0.017
97.36	-49.93	-0.017
97.40	-49.93	-0.017
97.44	-49.93	-0.017
97.48	-49.93	-0.017
97.52	-49.93	-0.017
97.56	-49.93	-0.017
97.60	-49.93	-0.017
97.64	-49.93	-0.017
97.68	-49.93	-0.017
97.72	-49.93	-0.017
97.76	-49.93	-0.017
97.80	-49.93	-0.017
97.84	-49.93	-0.017
97.88	-49.93	-0.017
97.92	-49.93	-0.017
97.96	-49.93	-0.017
98.00	-49.93	-0.017
98.04	-49.93	-0.017
98.08	-49.93	-0.017
98.12	-49.93	-0.017
98.16	-49.93	-0.017
98.20	-49.93	-0.017
98.24	-49.93	-0.017
98.28	-49.93	-0.017
98.32	-49.93	-0.017
98.36	-49.93	-0.017
98.40	-49.93	-0.017
98.44	-49.93	-0.017
98.48	-49.93	-0.017
98.52	-49.93	-0.017
98.56	-49.93	-0.017
98.60	-49.93	-0.017
98.64	-49.93	-0.017
98.68	-49.93	-0.017
98.72	-49.93	-0.017
98.76	-49.93	-0.017
98.80	-49.93	-0.017
98.84	-49.93	-0.017
98.88	-49.93	-0.017
98.92	-49.93	-0.017
98.96	-49.93	-0.016
99.00	-49.93	-0.016
99.04	-49.93	-0.016
99.08	-49.93	-0.016
99.12	-49.93	-0.016
99.16	-49.93	-0.016
99.20	-49.93	-0.016
99.24	-49.93	-0.016
99.28	-49.93	-0.016
99.32	-49.93	-0.016
99.36	-49.93	-0.016
99.40	-49.93	-0.016
99.44	-49.93	-0.016
99.48	-49.93	-0.016
99.52	-49.93	-0.016
99.56	-49.93	-0.016
99.60	-49.93	-0.016
99.64	-49.93	-0.016
99.68	-49.93	-0.016
99.72	-49.93	-0.016
99.76	-49.93	-0.016
[...]
168.35	-21.75	-0.077
168.41	-21.69	-0.077
168.47	-21.63	-0.077
168.53	-21.57	-0.078
168.58	-21.51	-0.078
168.64	-21.45	-0.078
168.70	-21.40	-0.079
168.76	-21.34	-0.079
168.82	-21.28	-0.079
168.88	-21.22	-0.080
168.93	-21.16	-0.080
168.99	-21.10	-0.080
169.05	-21.05	-0.081
169.11	-20.99	-0.081
169.17	-20.93	-0.081
169.23	-20.87	-0.082
169.28	-20.81	-0.082
169.34	-20.76	-0.083
169.40	-20.70	-0.083
169.46	-20.64	-0.083
169.52	-20.58	-0.084
169.58	-20.52	-0.084
169.63	-20.47	-0.085
169.69	-20.41	-0.085
169.75	-20.35	-0.085
169.81	-20.29	-0.086
169.87	-20.23	-0.086
169.93	-20.18	-0.087
169.98	-20.12	-0.087
170.04	-20.06	-0.087
170.10	-20.00	-0.088
170.16	-19.94	-0.088
170.22	-19.89	-0.089
170.28	-19.83	-0.089
170.33	-19.77	-0.090
170.39	-19.71	-0.091
170.45	-19.65	-0.091
170.51	-19.59	-0.092
170.57	-19.54	-0.092
170.63	-19.48	-0.093
170.68	-19.42	-0.093
170.74	-19.36	-0.094
170.80	-19.30	-0.094
170.86	-19.25	-0.095
170.92	-19.19	-0.096
170.98	-19.13	-0.096
171.03	-19.07	-0.097
171.09	-19.01	-0.097
171.15	-18.96	-0.098
171.21	-18.90	-0.098
171.27	-18.84	-0.099
171.33	-18.79	-0.100
171.38	-18.73	-0.100
171.44	-18.67	-0.101
171.50	-18.61	-0.102
171.56	-18.55	-0.103
171.62	-18.49	-0.103
171.68	-18.44	-0.104
171.73	-18.38	-0.105
171.79	-18.32	-0.105
171.85	-18.26	-0.106
171.91	-18.20	-0.107
171.97	-18.14	-0.108
172.03	-18.09	-0.108
172.08	-18.03	-0.109
172.14	-17.97	-0.110
172.20	-17.91	-0.111
172.26	-17.86	-0.111
172.32	-17.80	-0.112
172.38	-17.74	-0.113
172.43	-17.68	-0.114
172.49	-17.62	-0.115
172.55	-17.57	-0.116
172.61	-17.51	-0.117
172.67	-17.45	-0.118
172.73	-17.39	-0.119
172.78	-17.34	-0.120
172.84	-17.28	-0.121
172.90	-17.22	-0.122
172.96	-17.16	-0.123
173.02	-17.11	-0.124
173.08	-17.05	-0.125
173.13	-16.99	-0.127
173.19	-16.93	-0.128
173.25	-16.88	-0.129
173.31	-16.82	-0.130
173.37	-16.76	-0.131
173.43	-16.70	-0.133
173.48	-16.64	-0.134
173.54	-16.59	-0.135
173.60	-16.53	-0.137
173.66	-16.47	-0.138
173.72	-16.41	-0.139
173.78	-16.35	-0.141
173.83	-16.30	-0.142
173.89	-16.24	-0.143
173.95	-16.18	-0.145
174.01	-16.13	-0.146
174.07	-16.07	-0.148
174.13	-16.01	-0.151
174.18	-15.95	-0.153
174.24	-15.90	-0.155
174.30	-15.84	-0.156
174.36	-15.78	-0.158
174.42	-15.73	-0.161
174.48	-15.67	-0.163
174.53	-15.61	-0.165
174.59	-15.55	-0.167
174.65	-15.50	-0.170
174.71	-15.44	-0.172
174.77	-15.38	-0.175
174.83	-15.32	-0.177
174.88	-15.27	-0.180
174.94	-15.21	-0.182
175.00	-15.15	-0.185
175.06	-15.10	-0.187
175.12	-15.04	-0.190
175.18	-14.98	-0.193
175.23	-14.93	-0.195
175.29	-14.87	-0.199
175.35	-14.81	-0.202
175.41	-14.75	-0.205
175.47	-14.70	-0.208
175.53	-14.64	-0.210
175.58	-14.58	-0.214
175.64	-14.53	-0.218
175.70	-14.47	-0.221
175.76	-14.42	-0.225
175.82	-14.36	-0.229
175.88	-14.30	-0.232
175.93	-14.25	-0.235
175.99	-14.19	-0.239
176.05	-14.13	-0.243
176.11	-14.08	-0.247
176.17	-14.02	-0.251
176.23	-13.96	-0.255
176.28	-13.91	-0.259
176.34	-13.85	-0.263
176.40	-13.79	-0.267
176.46	-13.74	-0.272
176.52	-13.69	-0.276
176.58	-13.63	-0.280
176.63	-13.57	-0.284
176.69	-13.51	-0.288
176.75	-13.46	-0.292
176.81	-13.40	-0.296
176.87	-13.34	-0.299
176.93	-13.29	-0.301
176.98	-13.23	-0.301
177.04	-13.17	-0.302
177.10	-13.11	-0.299
177.16	-13.04	-0.286
177.22	-12.98	-0.264
177.28	-12.90	-0.230
177.33	-12.82	-0.184
177.39	-12.73	-0.136
177.45	-12.66	-0.101
177.51	-12.59	-0.079
177.57	-12.52	-0.067
177.63	-12.46	-0.061
177.68	-12.40	-0.058
177.74	-12.34	-0.056
177.80	-12.28	-0.055
177.86	-12.22	-0.054
177.92	-12.16	-0.054
177.98	-12.11	-0.053
178.03	-12.05	-0.053
178.09	-11.99	-0.052
178.15	-11.93	-0.052
178.21	-11.87	-0.052
178.27	-11.81	-0.052
178.33	-11.76	-0.051
178.38	-11.70	-0.051
178.44	-11.64	-0.051
178.50	-11.58	-0.051
178.56	-11.52	-0.051
178.62	-11.46	-0.051
178.68	-11.41	-0.051
178.73	-11.35	-0.051
178.79	-11.29	-0.051
178.85	-11.23	-0.051
178.91	-11.17	-0.051
178.97	-11.11	-0.051
179.03	-11.06	-0.051
179.08	-11.00	-0.051
179.14	-10.94	-0.051
179.20	-10.88	-0.051
179.26	-10.82	-0.051
179.32	-10.77	-0.051
179.38	-10.71	-0.051
179.43	-10.65	-0.051
179.49	-10.59	-0.051
179.55	-10.53	-0.051
179.61	-10.47	-0.051
179.67	-10.41	-0.051
179.73	-10.36	-0.051
179.78	-10.30	-0.051
179.84	-10.24	-0.051
179.90	-10.18	-0.051
179.96	-10.12	-0.051
180.02	-10.07	-0.051
180.08	-10.01	-0.051
180.13	-9.95	-0.051
180.19	-9.89	-0.051
180.25	-9.83	-0.051
180.31	-9.77	-0.051
180.37	-9.72	-0.051
180.43	-9.66	-0.051
180.48	-9.60	-0.051
180.54	-9.54	-0.051
180.60	-9.48	-0.051
180.66	-9.42	-0.051
180.72	-9.36	-0.051
180.78	-9.30	-0.051
180.83	-9.25	-0.051
180.89	-9.19	-0.051
180.95	-9.13	-0.051
181.01	-9.07	-0.051
181.07	-9.01	-0.051
181.13	-8.95	-0.051
181.18	-8.90	-0.051
181.24	-8.84	-0.051
181.30	-8.78	-0.051
181.36	-8.72	-0.051
181.42	-8.66	-0.051
181.48	-8.61	-0.051
181.53	-8.55	-0.051
181.59	-8.49	-0.051
181.65	-8.43	-0.051
181.71	-8.37	-0.051
181.77	-8.31	-0.051
181.83	-8.26	-0.051
181.88	-8.20	-0.051
181.94	-8.14	-0.051
182.00	-8.08	-0.051
182.06	-8.02	-0.051
182.12	-7.96	-0.051
182.18	-7.91	-0.051
182.23	-7.85	-0.051
182.29	-7.79	-0.051
182.35	-7.73	-0.051
182.41	-7.67	-0.051
182.47	-7.61	-0.051
182.53	-7.56	-0.051
182.58	-7.50	-0.051
182.64	-7.44	-0.051
182.70	-7.38	-0.051
182.76	-7.32	-0.051
182.82	-7.27	-0.051
182.88	-7.21	-0.051
182.93	-7.15	-0.051
182.99	-7.09	-0.051
183.05	-7.03	-0.051
183.11	-6.97	-0.051
183.17	-6.91	-0.051
183.23	-6.86	-0.051
183.28	-6.80	-0.051
183.34	-6.74	-0.051
183.40	-6.68	-0.051
183.46	-6.62	-0.051
183.52	-6.56	-0.051
183.58	-6.51	-0.051
183.63	-6.45	-0.051
183.69	-6.39	-0.051
183.75	-6.33	-0.051
183.81	-6.27	-0.051
183.87	-6.21	-0.051
183.93	-6.16	-0.051
183.98	-6.10	-0.051
184.04	-6.04	-0.051
184.10	-5.98	-0.051
184.16	-5.92	-0.051
184.22	-5.86	-0.051
184.28	-5.81	-0.051
184.33	-5.75	-0.051
184.39	-5.69	-0.051
184.45	-5.63	-0.051
184.51	-5.57	-0.051
184.57	-5.51	-0.051
184.63	-5.46	-0.051
184.68	-5.40	-0.051
184.74	-5.34	-0.051
184.80	-5.28	-0.051
184.86	-5.22	-0.051
184.92	-5.17	-0.051
184.98	-5.11	-0.051
185.03	-5.05	-0.051
185.09	-4.99	-0.051
185.15	-4.93	-0.051
185.21	-4.87	-0.051
185.27	-4.82	-0.051
185.33	-4.76	-0.051
185.38	-4.70	-0.051
185.44	-4.64	-0.051
185.50	-4.58	-0.051
185.56	-4.52	-0.051
185.62	-4.46	-0.051
185.68	-4.41	-0.051
185.73	-4.35	-0.051
185.79	-4.29	-0.051
185.85	-4.23	-0.051
185.91	-4.17	-0.051
185.97	-4.11	-0.051
186.03	-4.05	-0.051
186.08	-4.00	-0.051
186.14	-3.94	-0.051
186.20	-3.88	-0.051
186.26	-3.82	-0.051
186.32	-3.76	-0.051
186.38	-3.70	-0.051
186.43	-3.65	-0.051
186.49	-3.59	-0.051
186.55	-3.53	-0.051
186.61	-3.47	-0.051
186.67	-3.41	-0.051
186.73	-3.36	-0.051
186.78	-3.30	-0.051
186.84	-3.24	-0.051
186.90	-3.18	-0.051
186.96	-3.12	-0.051
187.02	-3.06	-0.051
187.08	-3.01	-0.051
187.13	-2.95	-0.051
187.19	-2.89	-0.051
187.25	-2.83	-0.051
187.31	-2.77	-0.051
187.37	-2.71	-0.051
187.43	-2.66	-0.051
187.48	-2.60	-0.051
187.54	-2.54	-0.051
187.60	-2.48	-0.051
187.66	-2.42	-0.051
187.72	-2.36	-0.051
187.78	-2.30	-0.051
187.83	-2.25	-0.051
187.89	-2.19	-0.051
187.95	-2.13	-0.051
188.01	-2.07	-0.051
188.07	-2.01	-0.051
188.13	-1.96	-0.051
188.18	-1.90	-0.051
188.24	-1.84	-0.051
188.30	-1.78	-0.051
188.36	-1.72	-0.051
188.42	-1.66	-0.051
188.48	-1.61	-0.051
188.53	-1.55	-0.051
188.59	-1.49	-0.051
188.65	-1.43	-0.051
188.71	-1.37	-0.051
188.77	-1.32	-0.051
188.83	-1.26	-0.051
188.88	-1.20	-0.051
188.94	-1.14	-0.051
189.00	-1.08	-0.051
189.06	-1.02	-0.051
189.12	-0.96	-0.051
189.18	-0.91	-0.051
189.23	-0.85	-0.051
189.29	-0.79	-0.051
189.35	-0.73	-0.051
189.41	-0.67	-0.051
189.47	-0.62	-0.051
189.53	-0.56	-0.051
189.58	-0.50	-0.051
189.64	-0.44	-0.051
189.70	-0.38	-0.051
189.76	-0.32	-0.051
189.82	-0.27	-0.051
189.88	-0.21	-0.051
189.93	-0.15	-0.051
189.99	-0.09	-0.051
190.05	-0.03	-0.051
190.11	0.02	-0.051
190.17	0.08	-0.051
190.23	0.14	-0.051
190.28	0.20	-0.051
190.34	0.26	-0.051
190.40	0.32	-0.051
190.46	0.38	-0.051
190.52	0.43	-0.051
190.58	0.49	-0.051
190.63	0.55	-0.051
190.69	0.61	-0.051
190.75	0.67	-0.051
190.81	0.73	-0.051
190.87	0.78	-0.051
190.93	0.84	-0.051
190.98	0.90	-0.051
191.04	0.96	-0.051
191.10	1.02	-0.051
191.16	1.08	-0.051
191.22	1.14	-0.051
191.28	1.19	-0.051
191.33	1.25	-0.051
191.39	1.31	-0.051
191.45	1.37	-0.051
191.51	1.43	-0.051
191.57	1.49	-0.051
191.63	1.54	-0.051
191.68	1.60	-0.051
191.74	1.66	-0.051
191.80	1.72	-0.051
191.86	1.77	-0.051
191.92	1.83	-0.051
191.98	1.89	-0.051
192.03	1.95	-0.051
192.09	2.01	-0.051
192.15	2.07	-0.051
192.21	2.13	-0.051
192.27	2.18	-0.051
192.33	2.24	-0.051
192.38	2.30	-0.051
192.44	2.36	-0.051
192.50	2.42	-0.051
192.56	2.48	-0.051
192.62	2.54	-0.051
192.68	2.59	-0.051
192.73	2.65	-0.051
192.79	2.71	-0.051
192.85	2.77	-0.051
192.91	2.82	-0.051
192.97	2.88	-0.051
193.03	2.94	-0.051
193.08	3.00	-0.051
193.14	3.06	-0.051
193.20	3.12	-0.051
193.26	3.18	-0.051
193.32	3.23	-0.051
193.38	3.29	-0.051
193.43	3.35	-0.051
193.49	3.41	-0.051
193.55	3.47	-0.051
193.61	3.53	-0.051
193.67	3.58	-0.051
193.73	3.64	-0.051
193.78	3.70	-0.051
193.84	3.76	-0.051
193.90	3.82	-0.051
193.96	3.88	-0.051
194.02	3.93	-0.051
194.08	3.99	-0.051
194.13	4.05	-0.051
194.19	4.11	-0.051
194.25	4.17	-0.051
194.31	4.23	-0.051
194.37	4.29	-0.051
194.43	4.34	-0.051
194.48	4.40	-0.051
194.54	4.46	-0.051
194.60	4.52	-0.051
194.66	4.58	-0.051
194.72	4.63	-0.051
194.78	4.69	-0.051
194.83	4.75	-0.051
194.89	4.81	-0.051
194.95	4.87	-0.051
195.01	4.93	-0.051
195.07	4.99	-0.051
195.13	5.04	-0.051
195.18	5.10	-0.051
195.24	5.16	-0.051
195.30	5.22	-0.051
195.36	5.27	-0.051
195.42	5.33	-0.051
195.48	5.39	-0.051
195.53	5.45	-0.051
195.59	5.51	-0.051
195.65	5.57	-0.051
195.71	5.62	-0.051
195.77	5.68	-0.051
195.83	5.74	-0.051
195.88	5.80	-0.051
195.94	5.86	-0.051
196.00	5.92	-0.051
196.06	5.98	-0.051
196.12	6.03	-0.051
196.18	6.09	-0.051
196.23	6.15	-0.051
196.29	6.21	-0.051
196.35	6.27	-0.051
196.41	6.33	-0.051
196.47	6.38	-0.051
196.53	6.44	-0.051
196.58	6.50	-0.051
196.64	6.56	-0.051
196.70	6.62	-0.051
196.76	6.67	-0.051
196.82	6.73	-0.051
196.88	6.79	-0.051
196.93	6.85	-0.051
196.99	6.91	-0.051
197.05	6.97	-0.051
197.11	7.03	-0.051
197.17	7.08	-0.051
197.23	7.14	-0.051
197.28	7.20	-0.051
197.34	7.26	-0.051
197.40	7.32	-0.051
197.46	7.38	-0.051
197.52	7.43	-0.051
197.58	7.49	-0.051
197.63	7.55	-0.051
197.69	7.61	-0.051
197.75	7.67	-0.051
197.81	7.73	-0.051
197.87	7.78	-0.051
197.93	7.84	-0.051
197.98	7.90	-0.051
198.04	7.96	-0.051
198.10	8.02	-0.051
198.16	8.08	-0.051
198.22	8.13	-0.051
198.28	8.19	-0.051
198.33	8.25	-0.051
198.39	8.31	-0.051
198.45	8.37	-0.051
198.51	8.43	-0.051
198.57	8.48	-0.051
198.63	8.54	-0.051
198.68	8.60	-0.051
198.74	8.66	-0.051
198.80	8.72	-0.051
198.86	8.78	-0.051
198.92	8.83	-0.051
198.98	8.89	-0.051
199.03	8.95	-0.051
199.09	9.01	-0.051
199.15	9.07	-0.051
199.21	9.13	-0.051
199.27	9.18	-0.051
199.33	9.24	-0.051
199.38	9.30	-0.051
199.44	9.36	-0.051
199.50	9.42	-0.051
199.56	9.48	-0.051
199.62	9.53	-0.051
199.68	9.59	-0.051
199.73	9.65	-0.051
199.79	9.71	-0.051
199.85	9.77	-0.051
199.91	9.83	-0.051
199.97	9.88	-0.051
200.03	9.94	-0.051
200.08	10.00	-0.051
200.14	10.06	-0.051
200.20	10.12	-0.051
200.26	10.18	-0.051
200.32	10.23	-0.051
200.38	10.29	-0.051
200.43	10.35	-0.051
200.49	10.41	-0.051
200.55	10.47	-0.051
200.61	10.53	-0.051
200.67	10.58	-0.051
200.73	10.64	-0.051
200.78	10.70	-0.051
200.84	10.76	-0.051
200.90	10.82	-0.051
200.96	10.88	-0.051
201.02	10.93	-0.051
201.08	10.99	-0.051
201.13	11.05	-0.051
201.19	11.11	-0.051
201.25	11.17	-0.051
201.31	11.22	-0.051
201.37	11.28	-0.051
201.43	11.34	-0.051
201.48	11.40	-0.051
201.54	11.46	-0.051
201.60	11.52	-0.051
201.66	11.58	-0.051
201.72	11.63	-0.051
201.78	11.69	-0.051
201.83	11.75	-0.051
201.89	11.81	-0.051
201.95	11.87	-0.051
202.01	11.93	-0.051
202.07	11.98	-0.051
202.13	12.04	-0.051
202.18	12.10	-0.051
202.24	12.16	-0.051
202.30	12.22	-0.051
202.36	12.27	-0.051
202.42	12.33	-0.051
202.48	12.39	-0.050
202.53	12.45	-0.050
202.59	12.51	-0.050
202.65	12.57	-0.050
202.71	12.62	-0.051
202.77	12.68	-0.051
202.83	12.74	-0.051
202.88	12.80	-0.051
202.94	12.86	-0.051
203.00	12.92	-0.051
203.06	12.97	-0.051
203.12	13.03	-0.051
203.18	13.09	-0.051
203.23	13.15	-0.051
203.29	13.21	-0.051
203.35	13.27	-0.051
203.41	13.32	-0.051
203.47	13.38	-0.051
203.53	13.44	-0.051
203.58	13.50	-0.051
203.64	13.56	-0.051
203.70	13.62	-0.050
203.76	13.67	-0.050
203.82	13.73	-0.050
203.88	13.79	-0.050
203.93	13.85	-0.051
203.99	13.91	-0.051
204.05	13.97	-0.051
204.11	14.02	-0.051
204.17	14.08	-0.051
204.23	14.14	-0.051
204.28	14.20	-0.051
204.34	14.26	-0.051
204.40	14.32	-0.051
204.46	14.37	-0.051
204.52	14.43	-0.051
204.58	14.49	-0.051
204.63	14.55	-0.051
204.69	14.61	-0.051
204.75	14.67	-0.051
204.81	14.72	-0.051
204.87	14.78	-0.051
204.93	14.84	-0.051
204.98	14.90	-0.051
205.04	14.96	-0.051
205.10	15.02	-0.051
205.16	15.07	-0.051
205.22	15.13	-0.051
205.28	15.19	-0.051
205.33	15.25	-0.051
205.39	15.31	-0.051
205.45	15.37	-0.051
205.51	15.42	-0.051
205.57	15.48	-0.051
205.63	15.54	-0.051
205.68	15.60	-0.051
205.74	15.66	-0.051
205.80	15.71	-0.051
205.86	15.77	-0.051
205.92	15.83	-0.051
205.98	15.89	-0.051
206.03	15.95	-0.051
206.09	16.01	-0.051
206.15	16.06	-0.051
206.21	16.12	-0.051
206.27	16.18	-0.051
206.33	16.24	-0.051
206.38	16.30	-0.051
206.44	16.36	-0.051
206.50	16.41	-0.051
206.56	16.47	-0.051
206.62	16.53	-0.051
206.68	16.59	-0.051
206.73	16.65	-0.051
206.79	16.71	-0.051
206.85	16.76	-0.051
206.91	16.82	-0.051
206.97	16.88	-0.051
207.03	16.94	-0.051
207.08	17.00	-0.051
207.14	17.06	-0.051
207.20	17.11	-0.051
207.26	17.17	-0.051
207.32	17.23	-0.051
207.38	17.29	-0.051
207.43	17.35	-0.051
207.49	17.41	-0.051
207.55	17.47	-0.051
207.61	17.52	-0.051
207.67	17.58	-0.051
207.73	17.64	-0.051
207.78	17.70	-0.051
207.84	17.76	-0.051
207.90	17.82	-0.051
207.96	17.87	-0.051
208.02	17.93	-0.051
208.08	17.99	-0.051
208.13	18.05	-0.051
208.19	18.11	-0.051
208.25	18.16	-0.051
208.31	18.22	-0.051
208.37	18.28	-0.051
208.43	18.34	-0.051
208.48	18.40	-0.051
208.54	18.46	-0.051
208.60	18.51	-0.051
208.66	18.57	-0.051
208.72	18.63	-0.051
208.78	18.69	-0.051
208.83	18.75	-0.051
208.89	18.81	-0.051
208.95	18.86	-0.051
209.01	18.92	-0.051
209.07	18.98	-0.051
209.13	19.04	-0.051
209.18	19.10	-0.051
209.24	19.16	-0.051
209.30	19.22	-0.051
209.36	19.27	-0.051
209.42	19.33	-0.051
209.48	19.39	-0.051
209.53	19.45	-0.051
209.59	19.51	-0.051
209.65	19.56	-0.051
209.71	19.62	-0.051
209.77	19.68	-0.051
209.83	19.74	-0.051
209.88	19.80	-0.051
209.94	19.86	-0.051
210.00	19.91	-0.051
210.06	19.97	-0.051
210.12	20.03	-0.051
210.18	20.09	-0.051
210.23	20.15	-0.051
210.29	20.20	-0.051
210.35	20.26	-0.051
210.41	20.32	-0.051
210.47	20.38	-0.051
210.53	20.44	-0.051
210.58	20.50	-0.051
210.64	20.56	-0.051
210.70	20.61	-0.051
210.76	20.67	-0.051
210.82	20.73	-0.051
210.88	20.79	-0.051
210.93	20.85	-0.051
210.99	20.90	-0.051
211.05	20.96	-0.051
211.11	21.02	-0.051
211.17	21.08	-0.051
211.23	21.14	-0.051
211.28	21.20	-0.051
211.34	21.25	-0.051
211.40	21.31	-0.051
211.46	21.37	-0.051
211.52	21.43	-0.051
211.58	21.49	-0.051
211.63	21.55	-0.051
211.69	21.60	-0.051
211.75	21.66	-0.051
211.81	21.72	-0.051
211.87	21.78	-0.051
211.93	21.84	-0.051
211.98	21.90	-0.050
212.04	21.95	-0.050
212.10	22.01	-0.050
212.16	22.07	-0.050
212.22	22.13	-0.050
212.28	22.19	-0.050
212.33	22.25	-0.050
212.39	22.31	-0.050
212.45	22.36	-0.050
212.51	22.42	-0.051
212.57	22.48	-0.050
212.63	22.54	-0.050
212.68	22.60	-0.050
212.74	22.66	-0.050
212.80	22.71	-0.051
212.86	22.77	-0.050
212.92	22.83	-0.050
212.98	22.89	-0.051
213.03	22.95	-0.051
213.09	23.01	-0.051
213.15	23.06	-0.051
213.21	23.12	-0.051
213.27	23.18	-0.051
213.33	23.24	-0.051
213.38	23.30	-0.051
213.44	23.36	-0.051
213.50	23.41	-0.051
213.56	23.47	-0.051
213.62	23.53	-0.051
213.68	23.59	-0.051
213.73	23.65	-0.051
213.79	23.71	-0.051
213.85	23.76	-0.051
213.91	23.82	-0.051
213.97	23.88	-0.051
214.03	23.94	-0.051
214.08	24.00	-0.051
214.14	24.05	-0.051
214.20	24.11	-0.051
214.26	24.17	-0.051
214.32	24.23	-0.051
214.38	24.29	-0.051
214.43	24.35	-0.051
214.49	24.40	-0.051
214.55	24.46	-0.051
214.61	24.52	-0.051
214.67	24.58	-0.051
214.73	24.64	-0.051
214.78	24.70	-0.051
214.84	24.75	-0.051
214.90	24.81	-0.051
214.96	24.87	-0.051
215.02	24.93	-0.050
215.08	24.99	-0.050
215.13	25.05	-0.050
215.19	25.10	-0.050
215.25	25.16	-0.050
215.31	25.22	-0.051
215.37	25.28	-0.051
215.43	25.34	-0.051
215.48	25.40	-0.051
215.54	25.45	-0.051
215.60	25.51	-0.051
215.66	25.57	-0.051
215.72	25.63	-0.051
215.78	25.69	-0.050
215.83	25.75	-0.051
215.89	25.81	-0.051
215.95	25.86	-0.051
216.01	25.92	-0.051
216.07	25.98	-0.051
216.13	26.04	-0.051
216.18	26.10	-0.051
216.24	26.16	-0.051
216.30	26.21	-0.051
216.36	26.27	-0.051
216.42	26.33	-0.051
216.48	26.39	-0.050
216.53	26.45	-0.050
216.59	26.50	-0.051
216.65	26.56	-0.051
216.71	26.62	-0.051
216.77	26.68	-0.051
216.83	26.74	-0.051
216.88	26.80	-0.051
216.94	26.85	-0.051
217.00	26.91	-0.051
217.06	26.97	-0.051
217.12	27.03	-0.051
217.18	27.09	-0.051
217.23	27.15	-0.051
217.29	27.20	-0.051
217.35	27.26	-0.051
217.41	27.32	-0.051
217.47	27.38	-0.051
217.53	27.44	-0.051
217.58	27.50	-0.051
217.64	27.55	-0.051
217.70	27.61	-0.051
217.76	27.67	-0.051
217.82	27.73	-0.051
217.88	27.79	-0.051
217.93	27.84	-0.051
217.99	27.90	-0.051
218.05	27.96	-0.051
218.11	28.02	-0.051
218.17	28.08	-0.051
218.23	28.14	-0.051
218.28	28.20	-0.051
218.34	28.25	-0.051
218.40	28.31	-0.051
218.46	28.37	-0.051
218.52	28.43	-0.051
218.58	28.49	-0.051
218.63	28.55	-0.051
218.69	28.60	-0.051
218.75	28.66	-0.051
218.81	28.72	-0.051
218.87	28.78	-0.051
218.93	28.84	-0.051
218.98	28.89	-0.051
219.04	28.95	-0.051
219.10	29.01	-0.051
219.16	29.07	-0.051
219.22	29.13	-0.051
219.28	29.19	-0.051
219.33	29.24	-0.051
219.39	29.30	-0.051
219.45	29.36	-0.051
219.51	29.42	-0.051
219.57	29.48	-0.051
219.63	29.54	-0.051
219.68	29.59	-0.051
219.74	29.65	-0.051
219.80	29.71	-0.051
219.86	29.77	-0.051
219.92	29.83	-0.051
219.98	29.89	-0.051
220.03	29.94	-0.051
220.09	30.00	-0.051
220.15	30.06	-0.051
220.21	30.12	-0.051
220.27	30.18	-0.051
220.33	30.24	-0.051
220.38	30.30	-0.051
220.44	30.35	-0.051
220.50	30.41	-0.051
220.56	30.47	-0.051
220.62	30.53	-0.051
220.68	30.59	-0.050
220.73	30.65	-0.050
220.79	30.70	-0.050
220.85	30.76	-0.050
220.91	30.82	-0.051
220.97	30.88	-0.051
221.03	30.94	-0.051
221.08	31.00	-0.051
221.14	31.05	-0.051
221.20	31.11	-0.051
221.26	31.17	-0.051
221.32	31.23	-0.051
221.38	31.29	-0.051
221.43	31.35	-0.051
221.49	31.40	-0.051
221.55	31.46	-0.051
221.61	31.52	-0.051
221.67	31.58	-0.051
221.73	31.64	-0.051
221.78	31.69	-0.051
221.84	31.75	-0.051
221.90	31.81	-0.051
221.96	31.87	-0.051
222.02	31.93	-0.051
222.08	31.99	-0.051
222.13	32.04	-0.051
222.19	32.10	-0.051
222.25	32.16	-0.051
222.31	32.22	-0.051
222.37	32.28	-0.051
222.43	32.34	-0.051
222.48	32.40	-0.051
222.54	32.45	-0.051
222.60	32.51	-0.051
222.66	32.57	-0.051
222.72	32.63	-0.051
222.78	32.69	-0.051
222.83	32.74	-0.051
222.89	32.80	-0.051
222.95	32.86	-0.051
223.01	32.92	-0.051
223.07	32.98	-0.051
223.13	33.04	-0.051
223.18	33.09	-0.051
223.24	33.15	-0.051
223.30	33.21	-0.051
223.36	33.27	-0.051
223.42	33.33	-0.051
223.48	33.39	-0.051
223.53	33.44	-0.051
223.59	33.50	-0.051
223.65	33.56	-0.051
223.71	33.62	-0.051
223.77	33.68	-0.051
223.83	33.74	-0.051
223.88	33.79	-0.051
223.94	33.85	-0.051
224.00	33.91	-0.051
224.06	33.97	-0.051
224.12	34.03	-0.051
224.18	34.09	-0.051
224.23	34.14	-0.051
224.29	34.20	-0.051
224.35	34.26	-0.051
224.41	34.32	-0.051
224.47	34.38	-0.051
224.53	34.44	-0.051
224.58	34.49	-0.051
224.64	34.55	-0.051
224.70	34.61	-0.051
224.76	34.67	-0.051
224.82	34.73	-0.051
224.88	34.79	-0.051
224.93	34.84	-0.051
224.99	34.90	-0.051
225.05	34.97	-0.051
225.11	35.13	-0.070
225.17	35.38	-0.106
225.23	35.71	-0.148
225.28	36.19	-0.209
225.34	36.75	-0.270
225.40	37.33	-0.313
225.46	37.93	-0.342
225.52	38.54	-0.359
225.58	39.14	-0.368
225.63	39.75	-0.372
225.69	40.36	-0.374
225.75	40.96	-0.374
225.81	41.56	-0.374
225.87	42.16	-0.374
225.93	42.76	-0.374
225.98	43.35	-0.373
226.04	43.94	-0.373
226.10	44.54	-0.372
226.16	45.13	-0.371
226.22	45.71	-0.370
226.28	46.30	-0.370
226.33	46.89	-0.369
226.39	47.48	-0.369
226.45	48.06	-0.368
226.51	48.65
226.56