File: [EMIM][DCA].txt
Filename	0313LTIL1
Instrument name	DSC2-01590 (192.168.1.10)
Operator
rundate	2025/3/13
Sample name	0313LTIL1
proceduresegments	Ramp 1.00 °C/min to -50.00 °C; Isothermal 60.0 min; Ramp 1.00 °C/min to 50.00 °C
[File Parameters]
Run date	2025/3/13 13:58:24
Trios version	5.1.1.46572
Original File Name
Current File Name	C:\ProgramData\TA Instruments\TRIOS\Data\0313LTIL1.tri
[Procedure]
Procedure Name
Sample Name	0313LTIL1
Sample Mass	8 mg
Pan Mass	0 mg
Pan Number	0
Reference Pan Number	0
Pan Type	Tzero Aluminum Hermetic
Comments
Project Name
Operator
Test	Custom
Unload Max Temperature	30
Unload Min Temperature	30
Load Max Temperature	30
Load Min Temperature	30
Stop on Gas Flow Error	Yes
[Signal List]
Signal #1	Time (min)
Signal #2	Temperature (°C)
Signal #3	Heat Flow (mW)
Signal #4	Delta T (µV)
Signal #5	Delta Tzero (µV)
Signal #6	Tzero Temperature (°C)
Signal #7	Cell Purge (mL/min)
Signal #8	Heater Temp (°C)
Signal #9	Power Delivered (W)
Signal #10	Reference Junction Temperature (°C)
Signal #11	Flange Temperature (°C)
Signal #12	Heat Flow Phase (rad)
Signal #13	Total Heat Capacity (J/°C)
[Configuration]
Company Name	ta
Instrument Name	DSC2-01590
Instrument Type	DSC25
Serial Number	DSC2-01590
IP	192.168.1.10
Location of Instrument	MFG
DisplayType	TianmaV2
Sample Interval 	0.1 s/pt
Selected Heat Flow	T1
Exotherm Direction	Up
Cell Serial	DRC2-03531
Lid Type	High Temperature
Cooler	RCS 90
Leave Cooler on at End of Sequence	On
Gas 2	Air
Gas Selected	Channel 1
Flow Rate	50 mL/min
Secondary Purge	Off
Licensed Heat Flow	Heat Flow T1
Modulation Licensed	Yes
[Versions]
Common IDD Version	1
Cortex Version	VER 2.10.2.31
Driver	5.0.0.6
GDM Version	1.0.3.3
TouchscreenVersion	1.0.0.16145
FEP Version	1.2.1.21
FEP Bootloader	2.0.0.5
FCM Version	1.1.0.3
FCM Bootloader	2.0.0.5
[Experiment Logs]
Experiment Log Entry # 2	Ramp Segment 1 C/min to -50 Started
Experiment Log Entry # 4	Isothermal Segment 60 min started
Experiment Log Entry # 6	Ramp Segment 1 C/min to 50 Started
[Method Log]
Method Log Entry # 1	(Ramp 2544) Ramp 1 °C/minute to -50 °C
Method Log Entry # 2	Isothermal 60 minutes
Method Log Entry # 3	(Ramp 2546) Ramp 1 °C/minute to 50 °C
Cell Serial	DRC2-03531
[T1 Calibration]
Date Applied	2022/8/30 17:06:21
Description	From -40.140 °C to 349.984 °C at 20.000°C/min
Gas Type	Nitrogen
Pan Type	None
Source Files 1	C:\ProgramData\TA Instruments\TRIOS\Data\Default(71).tri
Slope	-0.004052628
Offset	7.523911
Initial Temperature	-40.14014
GUID	1c40c2ec-416b-49dd-97cd-b9bbe1fdbf85
[TZero Calibration]
(Not Applied)
[Temperature Calibration]
Date Applied	2022/8/30 18:06:51
Description	From 106.590 °C to 186.590 °C at 10.000°C/min
Gas Type	Nitrogen
Pan Type	Tzero Aluminum Hermetic
Source Files 1	C:\ProgramData\TA Instruments\TRIOS\Data\Indium(6).tri
Measured 1	158.5283
Known 1	156.598
[Cell Constant Calibration]
Date Applied	2022/8/30 18:06:51
Description	From 106.590 °C to 186.590 °C at 10.000°C/min
Gas Type	Nitrogen
Pan Type	Tzero Aluminum Hermetic
Source Files 1	C:\ProgramData\TA Instruments\TRIOS\Data\Indium(6).tri
T1 KCell	0.9221585
Onset Slope	-7.918681 mW/°C
[Direct Cp Calibration]
(Not Applied)
[Rev Cp Calibration]
(Not Applied)
[step]
Ramp 1.00 °C/min to -50.00 °C
Time	Temperature	Heat Flow (Normalized)
min	°C	W/g
0.00
0.05	30.04
0.11	30.02	-0.013
0.16	29.99	-0.008
0.22	29.95	0.000
0.28	29.90	0.005
0.33	29.85	0.009
0.39	29.80	0.011
0.44	29.74	0.012
0.50	29.69	0.013
0.55	29.64	0.014
0.60	29.58	0.014
0.66	29.53	0.015
0.72	29.47	0.015
0.77	29.42	0.016
0.83	29.36	0.016
0.88	29.31	0.016
0.93	29.25	0.016
0.99	29.20	0.017
1.05	29.14	0.017
1.10	29.09	0.017
1.16	29.03	0.017
1.21	28.98	0.017
1.27	28.92	0.017
1.32	28.87	0.017
1.38	28.81	0.017
1.43	28.76	0.017
1.48	28.70	0.017
1.54	28.65	0.017
1.59	28.59	0.017
1.65	28.54	0.017
1.71	28.48	0.017
1.76	28.43	0.017
1.82	28.37	0.017
1.87	28.32	0.017
1.93	28.26	0.017
1.98	28.21	0.017
2.03	28.15	0.017
2.09	28.10	0.017
2.14	28.04	0.017
2.20	27.99	0.017
2.26	27.93	0.017
2.31	27.88	0.017
2.36	27.83	0.017
2.42	27.77	0.017
2.48	27.71	0.017
2.53	27.66	0.017
2.59	27.60	0.017
2.64	27.55	0.017
2.69	27.49	0.017
2.75	27.44	0.017
2.81	27.38	0.017
2.86	27.33	0.017
2.91	27.27	0.017
2.97	27.22	0.017
3.03	27.16	0.017
3.08	27.11	0.017
3.14	27.05	0.017
3.19	27.00	0.017
3.24	26.94	0.017
3.30	26.89	0.017
3.36	26.83	0.017
3.41	26.78	0.017
3.46	26.72	0.017
3.52	26.67	0.017
3.58	26.62	0.017
3.63	26.56	0.017
3.69	26.51	0.017
3.74	26.45	0.017
3.79	26.39	0.017
3.85	26.34	0.017
3.91	26.29	0.017
3.96	26.23	0.017
4.01	26.17	0.017
4.07	26.12	0.017
4.13	26.06	0.017
4.18	26.01	0.017
4.24	25.95	0.017
4.29	25.90	0.017
4.35	25.84	0.017
4.40	25.79	0.017
4.45	25.73	0.017
4.51	25.68	0.017
4.56	25.63	0.017
4.62	25.57	0.017
4.68	25.51	0.017
4.73	25.46	0.017
4.79	25.41	0.017
4.84	25.35	0.017
4.90	25.30	0.017
4.95	25.24	0.017
5.00	25.19	0.017
5.06	25.13	0.017
5.11	25.08	0.017
5.17	25.02	0.017
5.23	24.96	0.017
5.28	24.91	0.017
5.34	24.86	0.017
5.39	24.80	0.017
5.45	24.75	0.017
5.50	24.69	0.017
5.55	24.64	0.017
5.61	24.58	0.017
5.66	24.53	0.017
5.72	24.47	0.017
5.78	24.42	0.017
5.83	24.36	0.017
5.89	24.31	0.017
5.94	24.25	0.017
6.00	24.20	0.017
6.05	24.14	0.017
6.10	24.09	0.017
6.16	24.03	0.017
6.21	23.98	0.017
6.27	23.92	0.017
6.33	23.87	0.017
6.38	23.81	0.017
6.44	23.75	0.017
6.49	23.70	0.017
6.55	23.65	0.017
6.60	23.59	0.017
6.65	23.54	0.017
6.71	23.48	0.017
6.76	23.43	0.017
6.82	23.37	0.017
6.88	23.32	0.017
6.93	23.26	0.017
6.99	23.21	0.017
7.04	23.15	0.017
7.10	23.10	0.017
7.15	23.04	0.017
7.20	22.98	0.017
7.26	22.93	0.017
7.31	22.87	0.017
7.37	22.82	0.017
7.43	22.77	0.017
7.48	22.71	0.017
7.54	22.65	0.017
7.59	22.60	0.017
7.65	22.55	0.017
7.70	22.49	0.017
7.75	22.44	0.017
7.81	22.38	0.017
7.86	22.33	0.017
7.92	22.27	0.017
7.98	22.22	0.017
8.03	22.16	0.017
8.09	22.11	0.017
8.14	22.05	0.017
8.20	22.00	0.017
8.25	21.94	0.017
8.30	21.89	0.017
8.36	21.83	0.017
8.41	21.78	0.017
8.47	21.72	0.017
8.53	21.67	0.017
8.58	21.61	0.017
8.63	21.56	0.017
8.69	21.50	0.017
8.75	21.45	0.017
8.80	21.39	0.017
8.85	21.34	0.017
8.91	21.28	0.017
8.97	21.23	0.016
9.02	21.17	0.016
9.08	21.12	0.016
9.13	21.06	0.016
9.18	21.00	0.016
9.24	20.95	0.016
9.30	20.90	0.017
9.35	20.84	0.017
9.40	20.79	0.017
9.46	20.73	0.017
9.52	20.68	0.017
9.57	20.62	0.017
9.63	20.57	0.017
9.68	20.51	0.017
9.73	20.46	0.017
9.79	20.40	0.016
9.85	20.35	0.016
9.90	20.29	0.016
9.95	20.24	0.016
10.01	20.18	0.016
10.07	20.13	0.016
10.12	20.07	0.016
10.18	20.02	0.016
10.23	19.96	0.016
10.28	19.91	0.016
10.34	19.85	0.016
10.40	19.80	0.016
10.45	19.74	0.016
10.50	19.69	0.016
10.56	19.63	0.017
10.62	19.58	0.017
10.67	19.52	0.017
10.73	19.47	0.017
10.78	19.41	0.017
10.83	19.36	0.017
10.89	19.30	0.017
10.95	19.24	0.017
11.00	19.19	0.017
11.05	19.14	0.017
11.11	19.08	0.017
11.17	19.03	0.017
11.22	18.97	0.017
11.28	18.92	0.017
11.33	18.86	0.017
11.38	18.81	0.016
11.44	18.75	0.016
11.50	18.70	0.016
11.55	18.64	0.016
11.60	18.59	0.016
11.66	18.53	0.016
11.72	18.48	0.016
11.77	18.42	0.016
11.83	18.37	0.016
11.88	18.31	0.016
11.93	18.26	0.016
11.99	18.20	0.016
12.05	18.15	0.016
12.10	18.09	0.016
12.15	18.04	0.016
12.21	17.98	0.016
12.27	17.93	0.016
12.32	17.87	0.016
12.38	17.82	0.016
12.43	17.76	0.016
12.48	17.71	0.016
12.54	17.65	0.016
12.60	17.60	0.016
12.65	17.54	0.016
12.70	17.49	0.016
12.76	17.43	0.016
12.82	17.38	0.016
12.87	17.32	0.016
12.93	17.27	0.016
12.98	17.21	0.016
13.03	17.16	0.016
13.09	17.10	0.016
13.15	17.05	0.016
13.20	16.99	0.016
13.25	16.94	0.016
13.31	16.88	0.016
13.37	16.83	0.016
13.42	16.77	0.016
13.48	16.72	0.016
13.53	16.66	0.016
13.58	16.61	0.016
13.64	16.55	0.016
13.70	16.50	0.016
13.75	16.44	0.016
13.80	16.39	0.016
13.86	16.33	0.016
13.92	16.28	0.016
13.97	16.22	0.016
14.03	16.17	0.016
14.08	16.11	0.016
14.13	16.06	0.016
14.19	16.00	0.016
14.25	15.95	0.016
14.30	15.89	0.016
14.35	15.84	0.016
14.41	15.78	0.016
14.47	15.73	0.016
14.52	15.67	0.016
14.58	15.62	0.016
14.63	15.56	0.016
14.68	15.51	0.016
14.74	15.45	0.016
14.80	15.40	0.016
14.85	15.34	0.016
14.90	15.29	0.016
14.96	15.23	0.016
15.02	15.18	0.016
15.07	15.12	0.016
15.13	15.07	0.016
15.18	15.01	0.016
15.23	14.96	0.016
15.29	14.91	0.016
15.35	14.85	0.016
15.40	14.79	0.016
15.45	14.74	0.016
15.51	14.68	0.016
15.57	14.63	0.016
15.62	14.57	0.016
15.68	14.52	0.016
15.73	14.46	0.016
15.78	14.41	0.016
15.84	14.35	0.016
15.90	14.30	0.016
15.95	14.25	0.016
16.00	14.19	0.016
16.06	14.13	0.016
16.12	14.08	0.016
16.17	14.02	0.016
16.23	13.97	0.016
16.28	13.91	0.016
16.33	13.86	0.016
16.39	13.80	0.016
16.45	13.75	0.016
16.50	13.69	0.016
16.55	13.64	0.016
16.61	13.58	0.016
16.67	13.53	0.016
16.72	13.47	0.016
16.78	13.42	0.016
16.83	13.36	0.016
16.88	13.31	0.016
16.94	13.25	0.016
17.00	13.20	0.016
17.05	13.15	0.016
17.11	13.09	0.016
17.16	13.04	0.016
17.22	12.98	0.016
17.27	12.92	0.016
17.33	12.87	0.016
17.38	12.82	0.016
17.43	12.76	0.016
17.49	12.70	0.016
17.54	12.65	0.016
17.60	12.60	0.016
17.66	12.54	0.016
17.71	12.49	0.016
17.77	12.43	0.016
17.82	12.37	0.016
17.88	12.32	0.016
17.93	12.26	0.016
17.98	12.21	0.016
18.04	12.16	0.016
18.09	12.10	0.016
18.15	12.05	0.016
18.21	11.99	0.016
18.26	11.94	0.016
18.32	11.88	0.016
18.37	11.82	0.016
18.43	11.77	0.016
18.48	11.72	0.016
18.53	11.66	0.016
18.59	11.61	0.016
18.64	11.55	0.016
18.70	11.50	0.016
18.76	11.44	0.016
18.81	11.39	0.016
18.87	11.33	0.016
18.92	11.28	0.016
18.98	11.22	0.016
19.03	11.16	0.016
19.08	11.11	0.016
19.14	11.06	0.016
19.19	11.00	0.016
19.25	10.95	0.016
19.31	10.89	0.016
19.36	10.83	0.016
19.42	10.78	0.016
19.47	10.73	0.016
19.53	10.67	0.016
19.58	10.61	0.016
19.63	10.56	0.016
19.69	10.51	0.016
19.74	10.45	0.016
19.80	10.40	0.016
19.86	10.34	0.016
19.91	10.29	0.016
19.97	10.23	0.016
20.02	10.18	0.016
20.08	10.12	0.016
20.13	10.07	0.016
20.18	10.01	0.016
20.24	9.96	0.016
20.29	9.90	0.016
20.35	9.85	0.016
20.41	9.79	0.016
20.46	9.74	0.016
20.52	9.68	0.016
20.57	9.63	0.016
20.63	9.57	0.016
20.68	9.52	0.016
20.73	9.46	0.016
20.79	9.41	0.016
20.84	9.35	0.016
20.90	9.30	0.016
20.96	9.24	0.016
21.01	9.19	0.016
21.07	9.13	0.016
21.12	9.08	0.016
21.18	9.02	0.016
21.23	8.97	0.016
21.28	8.91	0.016
21.34	8.86	0.016
21.39	8.80	0.016
21.45	8.75	0.016
21.51	8.69	0.016
21.56	8.64	0.016
21.62	8.58	0.016
21.67	8.53	0.016
21.73	8.47	0.016
21.78	8.42	0.016
21.83	8.36	0.016
21.89	8.31	0.016
21.94	8.25	0.016
22.00	8.20	0.016
22.06	8.14	0.016
22.11	8.09	0.016
22.17	8.03	0.016
22.22	7.98	0.016
22.28	7.92	0.016
22.33	7.87	0.016
22.38	7.81	0.016
22.44	7.76	0.016
22.49	7.70	0.016
22.55	7.65	0.016
22.61	7.59	0.016
22.66	7.54	0.016
22.72	7.48	0.016
22.77	7.43	0.016
22.83	7.37	0.016
22.88	7.32	0.016
22.93	7.26	0.016
22.99	7.21	0.016
23.04	7.15	0.016
23.10	7.10	0.016
23.16	7.04	0.016
23.21	6.99	0.016
23.27	6.93	0.016
23.32	6.88	0.016
23.38	6.82	0.016
23.43	6.77	0.016
23.48	6.71	0.016
23.54	6.66	0.016
23.59	6.60	0.016
23.65	6.55	0.016
23.71	6.49	0.016
23.76	6.44	0.016
23.82	6.38	0.016
23.87	6.33	0.016
23.93	6.27	0.016
23.98	6.22	0.016
24.03	6.16	0.016
24.09	6.11	0.016
24.14	6.05	0.016
24.20	6.00	0.016
24.26	5.94	0.016
24.31	5.89	0.016
24.37	5.83	0.016
24.42	5.78	0.016
24.48	5.72	0.016
24.53	5.67	0.016
24.58	5.61	0.016
24.64	5.56	0.016
24.69	5.50	0.016
24.75	5.45	0.016
24.81	5.39	0.016
24.86	5.34	0.016
24.92	5.28	0.016
24.97	5.23	0.016
25.03	5.17	0.016
25.08	5.12	0.016
25.13	5.06	0.016
25.19	5.01	0.016
25.24	4.95	0.016
25.30	4.90	0.016
25.36	4.84	0.016
25.41	4.79	0.016
25.47	4.73	0.016
25.52	4.68	0.016
25.58	4.62	0.016
25.63	4.57	0.016
25.68	4.51	0.016
25.74	4.46	0.016
25.79	4.40	0.016
25.85	4.35	0.016
25.91	4.29	0.016
25.96	4.24	0.016
26.02	4.18	0.016
26.07	4.13	0.016
26.13	4.08	0.016
26.18	4.02	0.016
26.23	3.96	0.016
26.29	3.91	0.016
26.34	3.85	0.016
26.40	3.80	0.016
26.46	3.74	0.016
26.51	3.69	0.016
26.57	3.63	0.016
26.62	3.58	0.016
26.68	3.52	0.016
26.73	3.47	0.016
26.78	3.41	0.016
26.84	3.36	0.016
26.89	3.30	0.016
26.95	3.25	0.016
27.01	3.19	0.016
27.06	3.14	0.016
27.12	3.08	0.016
27.17	3.03	0.016
27.23	2.97	0.016
27.28	2.92	0.016
27.33	2.87	0.016
27.39	2.81	0.016
27.44	2.75	0.016
27.50	2.70	0.016
27.56	2.64	0.016
27.61	2.59	0.016
27.67	2.53	0.016
27.72	2.48	0.016
27.78	2.42	0.016
27.83	2.37	0.016
27.88	2.31	0.016
27.94	2.26	0.016
27.99	2.20	0.016
28.05	2.15	0.016
28.11	2.09	0.016
28.16	2.04	0.016
28.22	1.98	0.016
28.27	1.93	0.016
28.33	1.87	0.016
28.38	1.82	0.016
28.43	1.76	0.016
28.49	1.71	0.016
28.54	1.65	0.016
28.60	1.60	0.016
28.66	1.54	0.016
28.71	1.49	0.016
28.77	1.44	0.016
28.82	1.38	0.016
28.88	1.32	0.016
28.93	1.27	0.016
28.98	1.22	0.016
29.04	1.16	0.016
29.09	1.10	0.016
29.15	1.05	0.016
29.21	1.00	0.016
29.26	0.94	0.016
29.32	0.88	0.016
29.37	0.83	0.016
29.43	0.78	0.016
29.48	0.72	0.016
29.53	0.67	0.016
29.59	0.61	0.016
29.64	0.56	0.016
29.70	0.50	0.016
29.76	0.44	0.016
29.81	0.39	0.016
29.87	0.33	0.016
29.92	0.28	0.016
29.98	0.22	0.016
30.03	0.17	0.016
30.08	0.11	0.016
30.14	0.06	0.016
30.19	0.01	0.016
30.25	-0.05	0.016
30.31	-0.10	0.016
30.36	-0.16	0.016
30.42	-0.21	0.016
30.47	-0.27	0.016
30.53	-0.32	0.016
30.58	-0.38	0.016
30.63	-0.44	0.016
30.69	-0.49	0.016
30.74	-0.54	0.016
30.80	-0.60	0.016
30.86	-0.65	0.016
30.91	-0.71	0.016
30.97	-0.77	0.016
31.02	-0.82	0.016
31.08	-0.87	0.016
31.13	-0.93	0.016
31.18	-0.98	0.016
31.24	-1.04	0.016
31.29	-1.09	0.016
31.35	-1.15	0.016
31.41	-1.20	0.016
31.46	-1.26	0.016
31.52	-1.32	0.016
31.57	-1.37	0.016
31.63	-1.42	0.016
31.68	-1.48	0.016
31.73	-1.53	0.016
31.79	-1.59	0.016
31.84	-1.64	0.016
31.90	-1.70	0.016
31.96	-1.75	0.016
32.01	-1.81	0.016
32.07	-1.86	0.016
32.12	-1.92	0.016
32.18	-1.98	0.016
32.23	-2.03	0.016
32.28	-2.09	0.016
32.34	-2.14	0.016
32.39	-2.19	0.016
32.45	-2.25	0.016
32.51	-2.30	0.016
32.56	-2.36	0.016
32.62	-2.41	0.016
32.67	-2.47	0.016
32.73	-2.52	0.016
32.78	-2.58	0.016
32.83	-2.63	0.016
32.89	-2.69	0.016
32.94	-2.74	0.016
33.00	-2.80	0.016
33.06	-2.85	0.016
33.11	-2.91	0.016
33.17	-2.96	0.016
33.22	-3.02	0.016
33.28	-3.07	0.016
33.33	-3.13	0.016
33.38	-3.18	0.016
33.44	-3.24	0.016
33.49	-3.29	0.016
33.55	-3.35	0.016
33.61	-3.40	0.016
33.66	-3.46	0.016
33.72	-3.51	0.016
33.77	-3.57	0.016
33.83	-3.62	0.016
33.88	-3.68	0.016
33.93	-3.73	0.016
33.99	-3.79	0.016
34.04	-3.84	0.016
34.10	-3.90	0.016
34.16	-3.95	0.016
34.21	-4.01	0.015
34.26	-4.06	0.015
34.32	-4.12	0.016
34.38	-4.17	0.015
34.43	-4.23	0.015
34.49	-4.28	0.016
34.54	-4.34	0.015
34.59	-4.39	0.015
34.65	-4.45	0.015
34.71	-4.50	0.015
34.76	-4.56	0.015
34.81	-4.61	0.015
34.87	-4.67	0.015
34.93	-4.72	0.015
34.98	-4.78	0.015
35.04	-4.83	0.015
35.09	-4.89	0.015
35.14	-4.94	0.015
35.20	-5.00	0.015
35.26	-5.05	0.015
35.31	-5.11	0.015
35.36	-5.16	0.015
35.42	-5.22	0.015
35.48	-5.27	0.015
35.53	-5.33	0.015
35.59	-5.38	0.015
35.64	-5.44	0.015
35.69	-5.49	0.015
35.75	-5.55	0.015
35.81	-5.60	0.015
35.86	-5.66	0.015
35.91	-5.71	0.015
35.97	-5.77	0.015
36.03	-5.82	0.015
36.08	-5.88	0.015
36.14	-5.93	0.015
36.19	-5.99	0.015
36.24	-6.04	0.015
36.30	-6.10	0.015
36.36	-6.15	0.015
36.41	-6.21	0.015
36.46	-6.26	0.015
36.52	-6.32	0.015
36.58	-6.37	0.015
36.63	-6.43	0.015
36.69	-6.48	0.015
36.74	-6.54	0.015
36.79	-6.59	0.015
36.85	-6.65	0.015
36.91	-6.70	0.015
36.96	-6.76	0.015
37.01	-6.81	0.015
37.07	-6.87	0.015
37.13	-6.92	0.015
37.18	-6.98	0.015
37.24	-7.03	0.015
37.29	-7.09	0.015
37.34	-7.14	0.015
37.40	-7.20	0.015
37.46	-7.25	0.015
37.51	-7.31	0.015
37.56	-7.36	0.015
37.62	-7.42	0.015
37.68	-7.47	0.015
37.73	-7.53	0.015
37.79	-7.58	0.015
37.84	-7.64	0.015
37.89	-7.69	0.015
37.95	-7.75	0.015
38.01	-7.80	0.015
38.06	-7.86	0.015
38.11	-7.91	0.015
38.17	-7.97	0.015
38.23	-8.02	0.015
38.28	-8.08	0.015
38.34	-8.13	0.015
38.39	-8.19	0.015
38.44	-8.24	0.015
38.50	-8.30	0.015
38.56	-8.35	0.015
38.61	-8.41	0.015
38.66	-8.46	0.015
38.72	-8.52	0.015
38.78	-8.57	0.015
38.83	-8.63	0.015
38.89	-8.68	0.015
38.94	-8.74	0.015
38.99	-8.79	0.015
39.05	-8.85	0.015
39.11	-8.90	0.015
39.16	-8.96	0.015
39.21	-9.01	0.015
39.27	-9.07	0.015
39.33	-9.12	0.015
39.38	-9.18	0.015
39.44	-9.23	0.015
39.49	-9.29	0.015
39.54	-9.34	0.015
39.60	-9.40	0.015
39.66	-9.45	0.015
39.71	-9.51	0.015
39.76	-9.56	0.015
39.82	-9.62	0.015
39.88	-9.67	0.015
39.93	-9.73	0.015
39.99	-9.78	0.015
40.04	-9.84	0.015
40.09	-9.89	0.015
40.15	-9.95	0.015
40.21	-10.00	0.015
40.26	-10.05	0.015
40.31	-10.11	0.015
40.37	-10.16	0.015
40.43	-10.22	0.015
40.48	-10.28	0.015
40.54	-10.33	0.015
40.59	-10.38	0.015
40.64	-10.44	0.015
40.70	-10.49	0.015
40.76	-10.55	0.015
40.81	-10.61	0.015
40.86	-10.66	0.015
40.92	-10.72	0.015
40.98	-10.77	0.015
41.03	-10.83	0.015
41.09	-10.88	0.015
41.14	-10.94	0.015
41.19	-10.99	0.015
41.25	-11.05	0.015
41.31	-11.10	0.015
41.36	-11.15	0.015
41.41	-11.21	0.015
41.47	-11.27	0.015
41.53	-11.32	0.015
41.58	-11.38	0.015
41.64	-11.43	0.015
41.69	-11.49	0.015
41.74	-11.54	0.015
41.80	-11.60	0.015
41.86	-11.65	0.015
41.91	-11.71	0.015
41.96	-11.76	0.015
42.02	-11.82	0.015
42.08	-11.87	0.015
42.13	-11.92	0.015
42.19	-11.98	0.015
42.24	-12.04	0.015
42.29	-12.09	0.015
42.35	-12.15	0.015
42.41	-12.20	0.015
42.46	-12.26	0.015
42.51	-12.31	0.015
42.57	-12.37	0.015
42.63	-12.42	0.015
42.68	-12.48	0.015
42.74	-12.53	0.015
42.79	-12.59	0.015
42.84	-12.64	0.015
42.90	-12.70	0.015
42.96	-12.75	0.015
43.01	-12.81	0.015
43.06	-12.86	0.015
43.12	-12.92	0.015
43.18	-12.97	0.015
43.23	-13.02	0.015
43.29	-13.08	0.015
43.34	-13.14	0.015
43.39	-13.19	0.015
43.45	-13.24	0.015
43.51	-13.30	0.015
43.56	-13.35	0.015
43.61	-13.41	0.015
43.67	-13.47	0.015
43.73	-13.52	0.015
43.78	-13.58	0.015
43.84	-13.63	0.015
43.89	-13.69	0.015
43.94	-13.74	0.015
44.00	-13.79	0.015
44.06	-13.85	0.015
44.11	-13.91	0.015
44.16	-13.96	0.015
44.22	-14.02	0.015
44.28	-14.07	0.015
44.33	-14.12	0.015
44.39	-14.18	0.015
44.44	-14.23	0.015
44.49	-14.29	0.015
44.55	-14.34	0.015
44.61	-14.40	0.015
44.66	-14.45	0.015
44.71	-14.51	0.015
44.77	-14.56	0.015
44.83	-14.62	0.015
44.88	-14.67	0.015
44.94	-14.73	0.015
44.99	-14.78	0.015
45.04	-14.84	0.015
45.10	-14.89	0.015
45.16	-14.95	0.015
45.21	-15.00	0.015
45.26	-15.06	0.015
45.32	-15.12	0.015
45.38	-15.17	0.015
45.43	-15.22	0.015
45.49	-15.28	0.015
45.54	-15.33	0.015
45.59	-15.39	0.015
45.65	-15.44	0.015
45.71	-15.50	0.015
45.76	-15.55	0.015
45.81	-15.61	0.015
45.87	-15.66	0.015
45.93	-15.72	0.015
45.98	-15.78	0.015
46.04	-15.83	0.015
46.09	-15.89	0.015
46.14	-15.94	0.015
46.20	-15.99	0.015
46.26	-16.05	0.015
46.31	-16.10	0.015
46.36	-16.16	0.015
46.42	-16.21	0.015
46.48	-16.27	0.015
46.53	-16.33	0.015
46.59	-16.38	0.015
46.64	-16.43	0.015
46.69	-16.49	0.015
46.75	-16.54	0.015
46.81	-16.60	0.015
46.86	-16.65	0.015
46.91	-16.71	0.015
46.97	-16.76	0.015
47.03	-16.82	0.015
47.08	-16.87	0.015
47.14	-16.93	0.015
47.19	-16.98	0.015
47.24	-17.04	0.015
47.30	-17.09	0.015
47.36	-17.15	0.015
47.41	-17.20	0.015
47.46	-17.26	0.015
47.52	-17.31	0.015
47.58	-17.37	0.015
47.63	-17.43	0.015
47.69	-17.48	0.015
47.74	-17.53	0.015
47.79	-17.59	0.015
47.85	-17.64	0.015
47.91	-17.70	0.015
47.96	-17.75	0.015
48.01	-17.81	0.015
48.07	-17.86	0.015
48.13	-17.92	0.015
48.18	-17.97	0.015
48.24	-18.03	0.015
48.29	-18.08	0.015
48.34	-18.14	0.015
48.40	-18.19	0.015
48.46	-18.25	0.015
48.51	-18.30	0.015
48.56	-18.36	0.015
48.62	-18.41	0.015
48.68	-18.47	0.015
48.73	-18.52	0.015
48.79	-18.58	0.015
48.84	-18.63	0.015
48.89	-18.69	0.015
48.95	-18.74	0.015
49.01	-18.80	0.015
49.06	-18.85	0.015
49.11	-18.91	0.015
49.17	-18.96	0.015
49.23	-19.02	0.015
49.28	-19.07	0.015
49.34	-19.13	0.015
49.39	-19.18	0.015
49.44	-19.24	0.015
49.50	-19.29	0.015
49.56	-19.35	0.015
49.61	-19.40	0.015
49.66	-19.46	0.015
49.72	-19.51	0.015
49.78	-19.57	0.015
49.83	-19.62	0.015
49.89	-19.68	0.015
49.94	-19.73	0.015
49.99	-19.79	0.015
50.05	-19.84	0.015
50.11	-19.90	0.015
50.16	-19.95	0.015
50.21	-20.01	0.015
50.27	-20.06	0.015
50.33	-20.12	0.015
50.38	-20.17	0.015
50.44	-20.23	0.015
50.49	-20.28	0.015
50.54	-20.34	0.015
50.60	-20.39	0.015
50.66	-20.45	0.015
50.71	-20.50	0.015
50.76	-20.56	0.015
50.82	-20.61	0.015
50.88	-20.67	0.015
50.93	-20.72	0.015
50.99	-20.78	0.015
51.04	-20.83	0.015
51.09	-20.89	0.015
51.15	-20.94	0.015
51.21	-21.00	0.015
51.26	-21.05	0.015
51.31	-21.11	0.015
51.37	-21.16	0.015
51.43	-21.22	0.015
51.48	-21.27	0.015
51.54	-21.33	0.015
51.59	-21.38	0.015
51.64	-21.44	0.015
51.70	-21.49	0.015
51.76	-21.55	0.015
51.81	-21.60	0.015
51.86	-21.66	0.015
51.92	-21.71	0.015
51.98	-21.77	0.015
52.03	-21.82	0.015
52.09	-21.88	0.015
52.14	-21.93	0.015
52.19	-21.99	0.015
52.25	-22.04	0.015
52.31	-22.10	0.015
52.36	-22.15	0.015
52.41	-22.21	0.015
52.47	-22.26	0.015
52.53	-22.32	0.015
52.58	-22.37	0.015
52.64	-22.43	0.015
52.69	-22.48	0.015
52.74	-22.54	0.015
52.80	-22.59	0.015
52.86	-22.65	0.015
52.91	-22.70	0.015
52.96	-22.76	0.015
53.02	-22.81	0.015
53.08	-22.87	0.015
53.13	-22.92	0.015
53.19	-22.98	0.015
53.24	-23.03	0.015
53.29	-23.09	0.015
53.35	-23.14	0.015
53.41	-23.20	0.015
53.46	-23.25	0.015
53.51	-23.31	0.015
53.57	-23.36	0.015
53.63	-23.42	0.015
53.68	-23.47	0.015
53.74	-23.53	0.015
53.79	-23.58	0.015
53.84	-23.64	0.015
53.90	-23.69	0.015
53.96	-23.75	0.015
54.01	-23.80	0.015
54.06	-23.86	0.015
54.12	-23.91	0.015
54.18	-23.97	0.015
54.23	-24.02	0.015
54.29	-24.08	0.015
54.34	-24.13	0.015
54.39	-24.19	0.015
54.45	-24.24	0.015
54.51	-24.30	0.015
54.56	-24.35	0.015
54.61	-24.41	0.015
54.67	-24.46	0.015
54.73	-24.52	0.015
54.78	-24.57	0.015
54.84	-24.63	0.015
54.89	-24.68	0.015
54.94	-24.74	0.015
55.00	-24.79	0.015
55.06	-24.85	0.015
55.11	-24.90	0.015
55.16	-24.96	0.015
55.22	-25.01	0.015
55.28	-25.07	0.015
55.33	-25.12	0.015
55.39	-25.18	0.015
55.44	-25.23	0.015
55.49	-25.29	0.015
55.55	-25.34	0.015
55.61	-25.40	0.015
55.66	-25.45	0.015
55.71	-25.51	0.015
55.77	-25.56	0.015
55.83	-25.62	0.015
55.88	-25.67	0.015
55.94	-25.73	0.015
55.99	-25.78	0.015
56.04	-25.84	0.015
56.10	-25.89	0.015
56.16	-25.95	0.015
56.21	-26.00	0.015
56.26	-26.06	0.015
56.32	-26.11	0.015
56.38	-26.17	0.015
56.43	-26.22	0.015
56.49	-26.28	0.015
56.54	-26.33	0.015
56.59	-26.39	0.015
56.65	-26.44	0.015
56.71	-26.50	0.015
56.76	-26.55	0.015
56.81	-26.61	0.015
56.87	-26.66	0.015
56.93	-26.72	0.015
56.98	-26.77	0.015
57.04	-26.83	0.015
57.09	-26.88	0.015
57.14	-26.94	0.015
57.20	-26.99	0.015
57.26	-27.05	0.015
57.31	-27.10	0.015
57.36	-27.16	0.015
57.42	-27.21	0.015
57.48	-27.27	0.015
57.53	-27.32	0.015
57.59	-27.38	0.015
57.64	-27.43	0.015
57.69	-27.49	0.015
57.75	-27.54	0.015
57.81	-27.60	0.015
57.86	-27.65	0.015
57.91	-27.71	0.015
57.97	-27.76	0.015
58.03	-27.82	0.015
58.08	-27.87	0.015
58.14	-27.93	0.015
58.19	-27.98	0.015
58.24	-28.04	0.015
58.30	-28.09	0.015
58.36	-28.15	0.015
58.41	-28.20	0.015
58.46	-28.26	0.015
58.52	-28.31	0.015
58.58	-28.37	0.015
58.63	-28.42	0.015
58.69	-28.48	0.015
58.74	-28.53	0.015
58.79	-28.59	0.015
58.85	-28.64	0.015
58.91	-28.70	0.015
58.96	-28.75	0.015
59.01	-28.81	0.015
59.07	-28.86	0.015
59.13	-28.92	0.015
59.18	-28.97	0.015
59.24	-29.03	0.015
59.29	-29.08	0.015
59.34	-29.14	0.015
59.40	-29.19	0.015
59.46	-29.25	0.015
59.51	-29.30	0.015
59.56	-29.36	0.015
59.62	-29.41	0.015
59.68	-29.47	0.015
59.73	-29.52	0.015
59.79	-29.58	0.015
59.84	-29.63	0.015
59.89	-29.69	0.015
59.95	-29.74	0.015
60.01	-29.80	0.015
60.06	-29.85	0.015
60.11	-29.91	0.015
60.17	-29.96	0.015
60.23	-30.02	0.015
60.28	-30.07	0.015
60.34	-30.13	0.015
60.39	-30.18	0.015
60.44	-30.24	0.015
60.50	-30.29	0.015
60.56	-30.35	0.015
60.61	-30.40	0.015
60.66	-30.46	0.015
60.72	-30.51	0.015
60.78	-30.57	0.015
60.83	-30.62	0.015
60.89	-30.68	0.015
60.94	-30.73	0.015
60.99	-30.79	0.015
61.05	-30.84	0.015
61.11	-30.90	0.015
61.16	-30.95	0.015
61.21	-31.01	0.015
61.27	-31.06	0.015
61.33	-31.12	0.015
61.38	-31.17	0.015
61.44	-31.23	0.015
61.49	-31.28	0.015
61.54	-31.34	0.015
61.60	-31.39	0.015
61.66	-31.45	0.015
61.71	-31.50	0.015
61.76	-31.55	0.015
61.82	-31.61	0.015
61.88	-31.67	0.015
61.93	-31.72	0.015
61.99	-31.77	0.015
62.04	-31.83	0.015
62.09	-31.89	0.015
62.15	-31.94	0.015
62.21	-32.00	0.015
62.26	-32.05	0.015
62.31	-32.11	0.015
62.37	-32.16	0.015
62.43	-32.22	0.015
62.48	-32.27	0.015
62.54	-32.33	0.015
62.59	-32.38	0.015
62.64	-32.44	0.015
62.70	-32.49	0.015
62.76	-32.55	0.015
62.81	-32.60	0.015
62.86	-32.66	0.015
62.92	-32.71	0.015
62.98	-32.76	0.015
63.03	-32.82	0.015
63.09	-32.87	0.015
63.14	-32.93	0.015
63.19	-32.98	0.015
63.25	-33.04	0.015
63.31	-33.09	0.015
63.36	-33.15	0.015
63.41	-33.21	0.015
63.47	-33.26	0.015
63.53	-33.32	0.015
63.58	-33.37	0.015
63.64	-33.43	0.015
63.69	-33.48	0.015
63.74	-33.54	0.015
63.80	-33.59	0.015
63.86	-33.65	0.015
63.91	-33.70	0.015
63.96	-33.76	0.015
64.02	-33.81	0.015
64.08	-33.86	0.015
64.13	-33.92	0.015
64.19	-33.97	0.015
64.24	-34.03	0.015
64.29	-34.08	0.015
64.35	-34.14	0.015
64.41	-34.19	0.015
64.46	-34.25	0.015
64.51	-34.31	0.015
64.57	-34.36	0.015
64.63	-34.42	0.015
64.68	-34.47	0.015
64.74	-34.53	0.015
64.79	-34.58	0.015
64.84	-34.63	0.015
64.90	-34.69	0.015
64.96	-34.74	0.015
65.01	-34.80	0.015
65.06	-34.85	0.015
65.12	-34.91	0.015
65.18	-34.96	0.015
65.23	-35.02	0.015
65.29	-35.08	0.015
65.34	-35.13	0.015
65.39	-35.19	0.015
65.45	-35.24	0.015
65.51	-35.29	0.015
65.56	-35.35	0.015
65.61	-35.40	0.015
65.67	-35.46	0.015
65.73	-35.51	0.015
65.78	-35.57	0.015
65.84	-35.63	0.015
65.89	-35.68	0.015
65.94	-35.74	0.015
66.00	-35.79	0.015
66.06	-35.84	0.015
66.11	-35.90	0.015
66.16	-35.96	0.015
66.22	-36.01	0.015
66.28	-36.07	0.015
66.33	-36.12	0.015
66.39	-36.17	0.015
66.44	-36.23	0.015
66.49	-36.28	0.015
66.55	-36.34	0.015
66.61	-36.39	0.015
66.66	-36.45	0.015
66.71	-36.51	0.015
66.77	-36.56	0.015
66.83	-36.61	0.015
66.88	-36.67	0.015
66.94	-36.72	0.015
66.99	-36.78	0.015
67.04	-36.83	0.015
67.10	-36.89	0.015
67.16	-36.95	0.015
67.21	-37.00	0.015
67.26	-37.05	0.015
67.32	-37.11	0.015
67.38	-37.16	0.015
67.43	-37.22	0.015
67.49	-37.27	0.015
67.54	-37.33	0.015
67.59	-37.38	0.015
67.65	-37.44	0.015
67.71	-37.50	0.015
67.76	-37.55	0.015
67.81	-37.61	0.015
67.87	-37.66	0.015
67.93	-37.71	0.015
67.98	-37.77	0.015
68.04	-37.82	0.015
68.09	-37.88	0.015
68.14	-37.93	0.015
68.20	-37.99	0.015
68.26	-38.04	0.015
68.31	-38.10	0.015
68.36	-38.15	0.015
68.42	-38.21	0.015
68.48	-38.26	0.015
68.53	-38.32	0.015
68.59	-38.37	0.015
68.64	-38.43	0.015
68.70	-38.48	0.015
68.75	-38.54	0.015
68.80	-38.59	0.015
68.86	-38.65	0.015
68.91	-38.70	0.015
68.97	-38.76	0.015
69.03	-38.81	0.015
69.08	-38.87	0.015
69.14	-38.92	0.015
69.19	-38.98	0.015
69.25	-39.04	0.015
69.30	-39.09	0.015
69.35	-39.14	0.015
69.41	-39.20	0.015
69.46	-39.25	0.015
69.52	-39.31	0.015
69.58	-39.36	0.015
69.63	-39.42	0.015
69.69	-39.47	0.015
69.74	-39.53	0.015
69.80	-39.58	0.015
69.85	-39.64	0.015
69.90	-39.69	0.015
69.96	-39.75	0.015
70.01	-39.80	0.015
70.07	-39.86	0.015
70.13	-39.91	0.015
70.18	-39.97	0.015
70.24	-40.02	0.015
70.29	-40.08	0.015
70.35	-40.13	0.015
70.40	-40.19	0.015
70.45	-40.24	0.015
70.51	-40.29	0.029
70.56	-40.32	0.083
70.62	-40.34	0.141
70.68	-40.36	0.197
70.73	-40.37	0.285
70.79	-40.34	0.451
70.84	-40.22	0.765
70.90	-39.97	1.325
70.95	-39.74	1.845
71.00	-39.54	2.325
71.06	-39.33	2.795
71.11	-39.21	3.131
71.17	-39.20	3.245
71.23	-39.36	3.056
71.28	-39.77	2.392
71.34	-40.24	1.619
71.39	-40.61	1.053
71.45	-40.86	0.689
71.50	-41.04	0.471
71.55	-41.16	0.338
71.61	-41.26	0.260
71.66	-41.34	0.216
71.72	-41.41	0.192
71.78	-41.48	0.164
71.83	-41.56	0.118
71.89	-41.64	0.084
71.94	-41.70	0.063
72.00	-41.76	0.051
72.05	-41.82	0.044
72.10	-41.88	0.039
72.16	-41.94	0.036
72.21	-41.99	0.033
72.27	-42.05	0.032
72.33	-42.10	0.031
72.38	-42.16	0.030
72.44	-42.22	0.029
72.49	-42.27	0.028
72.55	-42.33	0.028
72.60	-42.38	0.027
72.65	-42.44	0.026
72.71	-42.49	0.025
72.76	-42.55	0.024
72.82	-42.60	0.024
72.88	-42.66	0.023
72.93	-42.71	0.022
72.99	-42.77	0.022
73.04	-42.83	0.021
73.10	-42.88	0.021
73.15	-42.93	0.020
73.20	-42.99	0.020
73.26	-43.05	0.019
73.31	-43.10	0.019
73.37	-43.16	0.019
73.43	-43.21	0.018
73.48	-43.27	0.018
73.54	-43.32	0.017
73.59	-43.38	0.017
73.65	-43.43	0.017
73.70	-43.49	0.016
73.75	-43.54	0.016
73.81	-43.60	0.016
73.86	-43.65	0.016
73.92	-43.71	0.015
73.98	-43.76	0.015
74.03	-43.82	0.015
74.09	-43.87	0.015
74.14	-43.93	0.014
74.20	-43.98	0.014
74.25	-44.04	0.014
74.30	-44.09	0.014
74.36	-44.15	0.014
74.41	-44.20	0.013
74.47	-44.26	0.013
74.53	-44.31	0.013
74.58	-44.37	0.013
74.64	-44.42	0.013
74.69	-44.48	0.013
74.75	-44.53	0.013
74.80	-44.59	0.012
74.85	-44.64	0.012
74.91	-44.70	0.012
74.96	-44.75	0.012
75.02	-44.81	0.013
75.08	-44.86	0.013
75.13	-44.92	0.013
75.19	-44.97	0.013
75.24	-45.03	0.013
75.30	-45.08	0.013
75.35	-45.14	0.013
75.40	-45.19	0.012
75.46	-45.25	0.012
75.51	-45.30	0.012
75.57	-45.36	0.012
75.63	-45.41	0.012
75.68	-45.47	0.011
75.74	-45.52	0.011
75.79	-45.58	0.011
75.85	-45.63	0.011
75.90	-45.69	0.011
75.95	-45.74	0.011
76.01	-45.80	0.011
76.06	-45.85	0.011
76.12	-45.91	0.010
76.18	-45.96	0.010
76.23	-46.02	0.010
76.29	-46.07	0.010
76.34	-46.13	0.010
76.40	-46.18	0.010
76.45	-46.24	0.010
76.50	-46.29	0.010
76.56	-46.35	0.010
76.61	-46.40	0.010
76.67	-46.46	0.010
76.73	-46.51	0.010
76.78	-46.57	0.010
76.84	-46.63	0.010
76.89	-46.68	0.010
76.95	-46.73	0.010
77.00	-46.79	0.010
77.05	-46.84	0.010
77.11	-46.90	0.009
77.16	-46.95	0.009
77.22	-47.01	0.009
77.28	-47.06	0.009
77.33	-47.12	0.009
77.39	-47.17	0.009
77.44	-47.23	0.009
77.50	-47.28	0.009
77.55	-47.34	0.009
77.60	-47.39	0.009
77.66	-47.45	0.009
77.71	-47.50	0.009
77.77	-47.56	0.009
77.83	-47.61	0.009
77.88	-47.67	0.009
77.94	-47.72	0.009
77.99	-47.78	0.009
78.05	-47.83	0.009
78.10	-47.89	0.009
78.15	-47.94	0.009
78.21	-48.00	0.009
78.26	-48.05	0.009
78.32	-48.11	0.009
78.38	-48.16	0.009
78.43	-48.22	0.009
78.49	-48.27	0.009
78.54	-48.33	0.009
78.60	-48.38	0.008
78.65	-48.44	0.008
78.70	-48.49	0.008
78.76	-48.55	0.008
78.81	-48.60	0.008
78.87	-48.66	0.008
78.93	-48.71	0.008
78.98	-48.77	0.008
79.04	-48.82	0.008
79.09	-48.88	0.008
79.15	-48.93	0.008
79.20	-48.99	0.009
79.25	-49.04	0.010
79.31	-49.10	0.012
79.36	-49.15	0.014
79.42	-49.20	0.015
79.48	-49.26	0.016
79.53	-49.31	0.017
79.59	-49.37	0.018
79.64	-49.42	0.018
79.70	-49.48	0.018
79.75	-49.54	0.016
79.80	-49.59	0.014
79.86	-49.65	0.013
79.91	-49.70	0.012
79.97	-49.76	0.011
80.00	-49.79	0.011

[step]
Isothermal 60.0 min
Time	Temperature	Heat Flow (Normalized)
min	°C	W/g
80.00	-49.79	0.011
80.05	-49.83	0.011
80.09	-49.86	0.010
80.13	-49.88	0.006
80.16	-49.90	0.000
80.20	-49.90	-0.004
80.25	-49.91	-0.007
80.29	-49.92	-0.009
80.33	-49.92	-0.010
80.36	-49.92	-0.011
80.40	-49.92	-0.012
80.45	-49.92	-0.012
80.49	-49.92	-0.013
80.53	-49.93	-0.013
80.56	-49.93	-0.014
80.60	-49.93	-0.014
80.65	-49.93	-0.014
80.69	-49.93	-0.015
80.73	-49.93	-0.015
80.76	-49.93	-0.015
80.80	-49.93	-0.016
80.85	-49.93	-0.016
80.89	-49.93	-0.016
80.93	-49.93	-0.016
80.96	-49.93	-0.016
81.00	-49.93	-0.016
81.05	-49.93	-0.016
81.09	-49.93	-0.016
81.13	-49.93	-0.016
81.16	-49.93	-0.016
81.20	-49.93	-0.017
81.25	-49.93	-0.017
81.29	-49.93	-0.017
81.33	-49.93	-0.017
81.36	-49.93	-0.017
81.40	-49.93	-0.017
81.45	-49.93	-0.017
81.49	-49.93	-0.017
81.53	-49.93	-0.017
81.56	-49.93	-0.017
81.60	-49.93	-0.017
81.65	-49.93	-0.017
81.69	-49.93	-0.017
81.73	-49.93	-0.017
81.76	-49.93	-0.017
81.80	-49.93	-0.017
81.85	-49.93	-0.017
81.89	-49.93	-0.017
81.93	-49.93	-0.017
81.96	-49.93	-0.017
82.00	-49.93	-0.017
82.05	-49.93	-0.017
82.09	-49.93	-0.017
82.13	-49.93	-0.017
82.16	-49.93	-0.017
82.20	-49.93	-0.017
82.25	-49.93	-0.017
82.29	-49.93	-0.017
82.33	-49.93	-0.017
82.36	-49.93	-0.017
82.40	-49.93	-0.017
82.45	-49.93	-0.017
82.49	-49.93	-0.017
82.53	-49.93	-0.017
82.56	-49.93	-0.017
82.60	-49.93	-0.017
82.65	-49.93	-0.017
82.69	-49.93	-0.017
82.73	-49.93	-0.017
82.76	-49.93	-0.017
82.80	-49.93	-0.017
82.85	-49.93	-0.017
82.89	-49.93	-0.017
82.93	-49.93	-0.017
82.96	-49.93	-0.017
83.00	-49.93	-0.017
83.05	-49.93	-0.017
83.09	-49.93	-0.017
83.13	-49.93	-0.017
83.16	-49.93	-0.017
83.20	-49.93	-0.017
83.25	-49.93	-0.017
83.29	-49.93	-0.017
83.33	-49.93	-0.017
83.36	-49.93	-0.017
83.40	-49.93	-0.017
83.45	-49.93	-0.017
83.49	-49.93	-0.017
83.53	-49.93	-0.017
83.56	-49.93	-0.017
83.60	-49.93	-0.017
83.65	-49.93	-0.017
83.69	-49.93	-0.017
83.73	-49.93	-0.017
83.76	-49.93	-0.017
83.80	-49.93	-0.017
83.85	-49.93	-0.017
83.89	-49.93	-0.017
83.93	-49.93	-0.017
83.96	-49.93	-0.017
84.00	-49.93	-0.017
84.05	-49.93	-0.017
84.09	-49.93	-0.017
84.13	-49.93	-0.017
84.16	-49.93	-0.017
84.20	-49.93	-0.017
84.25	-49.93	-0.017
84.29	-49.93	-0.017
84.33	-49.93	-0.017
84.36	-49.93	-0.017
84.40	-49.93	-0.017
84.45	-49.93	-0.017
84.49	-49.93	-0.017
84.53	-49.93	-0.017
84.56	-49.93	-0.017
84.60	-49.93	-0.017
84.65	-49.93	-0.017
84.69	-49.93	-0.017
84.73	-49.93	-0.017
84.76	-49.93	-0.017
84.80	-49.93	-0.017
84.85	-49.93	-0.017
84.89	-49.93	-0.017
84.93	-49.93	-0.017
84.96	-49.93	-0.017
85.00	-49.93	-0.017
85.05	-49.93	-0.017
85.09	-49.93	-0.017
85.13	-49.93	-0.017
85.16	-49.93	-0.017
85.20	-49.93	-0.017
85.25	-49.93	-0.017
85.29	-49.93	-0.017
85.33	-49.93	-0.017
85.36	-49.93	-0.017
85.40	-49.93	-0.017
85.45	-49.93	-0.017
85.49	-49.93	-0.017
85.53	-49.93	-0.017
85.56	-49.93	-0.017
85.60	-49.93	-0.017
85.65	-49.93	-0.017
85.69	-49.93	-0.017
85.73	-49.93	-0.017
85.76	-49.93	-0.017
85.80	-49.93	-0.017
85.85	-49.93	-0.017
85.89	-49.93	-0.017
85.93	-49.93	-0.017
85.96	-49.93	-0.017
86.00	-49.93	-0.017
86.05	-49.93	-0.017
86.09	-49.93	-0.017
86.13	-49.93	-0.017
86.16	-49.93	-0.017
86.20	-49.93	-0.017
86.25	-49.93	-0.017
86.29	-49.93	-0.017
86.33	-49.93	-0.017
86.36	-49.93	-0.017
86.40	-49.93	-0.017
86.45	-49.93	-0.017
86.49	-49.93	-0.017
86.53	-49.93	-0.017
86.56	-49.93	-0.017
86.60	-49.93	-0.017
86.65	-49.93	-0.017
86.69	-49.93	-0.017
86.73	-49.93	-0.017
86.76	-49.93	-0.017
86.80	-49.93	-0.017
86.85	-49.93	-0.017
86.89	-49.93	-0.017
86.93	-49.93	-0.017
86.96	-49.93	-0.017
87.00	-49.93	-0.017
87.05	-49.93	-0.017
87.09	-49.93	-0.017
87.13	-49.93	-0.017
87.16	-49.93	-0.017
87.20	-49.93	-0.017
87.25	-49.93	-0.017
87.29	-49.93	-0.017
87.33	-49.93	-0.017
87.36	-49.93	-0.017
87.40	-49.93	-0.017
87.45	-49.93	-0.017
87.49	-49.93	-0.017
87.53	-49.93	-0.017
87.56	-49.93	-0.017
87.60	-49.93	-0.017
87.65	-49.93	-0.017
87.69	-49.93	-0.017
87.73	-49.93	-0.017
87.76	-49.93	-0.017
87.80	-49.93	-0.017
87.85	-49.93	-0.017
87.89	-49.93	-0.017
87.93	-49.93	-0.017
87.96	-49.93	-0.017
88.00	-49.93	-0.017
88.05	-49.93	-0.017
88.09	-49.93	-0.017
88.13	-49.93	-0.017
88.16	-49.93	-0.017
88.20	-49.93	-0.017
88.25	-49.93	-0.017
88.29	-49.93	-0.017
88.33	-49.93	-0.017
88.36	-49.93	-0.017
88.40	-49.93	-0.017
88.45	-49.93	-0.017
88.49	-49.93	-0.017
88.53	-49.93	-0.017
88.56	-49.93	-0.017
88.60	-49.93	-0.017
88.65	-49.93	-0.017
88.69	-49.93	-0.017
88.73	-49.93	-0.017
88.76	-49.93	-0.017
88.80	-49.93	-0.017
88.85	-49.93	-0.017
88.89	-49.93	-0.017
88.93	-49.93	-0.017
88.96	-49.93	-0.017
89.00	-49.93	-0.017
89.05	-49.93	-0.017
89.09	-49.93	-0.017
89.13	-49.93	-0.017
89.16	-49.93	-0.017
89.20	-49.93	-0.017
89.25	-49.93	-0.017
89.29	-49.93	-0.017
89.33	-49.93	-0.017
89.36	-49.93	-0.017
89.40	-49.93	-0.017
89.45	-49.93	-0.017
89.49	-49.93	-0.017
89.53	-49.93	-0.017
89.56	-49.93	-0.017
89.60	-49.93	-0.017
89.65	-49.93	-0.017
89.69	-49.93	-0.017
89.73	-49.93	-0.017
89.76	-49.93	-0.017
89.80	-49.93	-0.017
89.85	-49.93	-0.017
89.89	-49.93	-0.017
89.93	-49.93	-0.017
89.96	-49.93	-0.017
90.00	-49.93	-0.017
90.05	-49.93	-0.017
90.09	-49.93	-0.017
90.13	-49.93	-0.017
90.16	-49.93	-0.017
90.20	-49.93	-0.017
90.25	-49.93	-0.017
90.29	-49.93	-0.017
90.33	-49.93	-0.017
90.36	-49.93	-0.017
90.40	-49.93	-0.017
90.45	-49.93	-0.017
90.49	-49.93	-0.017
90.53	-49.93	-0.017
90.56	-49.93	-0.017
90.60	-49.93	-0.017
90.65	-49.93	-0.017
90.69	-49.93	-0.017
90.73	-49.93	-0.017
90.76	-49.93	-0.017
90.80	-49.93	-0.017
90.85	-49.93	-0.017
90.89	-49.93	-0.017
90.93	-49.93	-0.017
90.96	-49.93	-0.017
91.00	-49.93	-0.017
91.05	-49.93	-0.017
91.09	-49.93	-0.017
91.13	-49.93	-0.017
91.16	-49.93	-0.017
91.20	-49.93	-0.017
91.25	-49.93	-0.017
91.29	-49.93	-0.017
91.33	-49.93	-0.017
91.36	-49.93	-0.017
91.40	-49.93	-0.017
91.45	-49.93	-0.017
91.49	-49.93	-0.017
91.53	-49.93	-0.017
91.56	-49.93	-0.017
91.60	-49.93	-0.017
91.65	-49.93	-0.017
91.69	-49.93	-0.017
91.73	-49.93	-0.017
91.76	-49.93	-0.017
91.80	-49.93	-0.017
91.85	-49.93	-0.017
91.89	-49.93	-0.017
91.93	-49.93	-0.017
91.96	-49.93	-0.017
92.00	-49.93	-0.017
92.05	-49.93	-0.017
92.09	-49.93	-0.017
92.13	-49.93	-0.017
92.16	-49.93	-0.017
92.20	-49.93	-0.017
92.25	-49.93	-0.017
92.29	-49.93	-0.017
92.33	-49.93	-0.017
92.36	-49.93	-0.017
92.40	-49.93	-0.017
92.45	-49.93	-0.017
92.49	-49.93	-0.017
92.53	-49.93	-0.017
92.56	-49.93	-0.017
92.60	-49.93	-0.017
92.65	-49.93	-0.017
92.69	-49.93	-0.017
92.73	-49.93	-0.017
92.76	-49.93	-0.017
92.80	-49.93	-0.017
92.85	-49.93	-0.017
92.89	-49.93	-0.017
92.93	-49.93	-0.017
92.96	-49.93	-0.017
93.00	-49.93	-0.017
93.05	-49.93	-0.017
93.09	-49.93	-0.017
93.13	-49.93	-0.017
93.16	-49.93	-0.017
93.20	-49.93	-0.017
93.25	-49.93	-0.017
93.29	-49.93	-0.017
93.33	-49.93	-0.017
93.36	-49.93	-0.017
93.40	-49.93	-0.017
93.45	-49.93	-0.017
93.49	-49.93	-0.017
93.53	-49.93	-0.017
93.56	-49.93	-0.017
93.60	-49.93	-0.017
93.65	-49.93	-0.017
93.69	-49.93	-0.017
93.73	-49.93	-0.017
93.76	-49.93	-0.017
93.80	-49.93	-0.017
93.85	-49.93	-0.017
93.89	-49.93	-0.017
93.93	-49.93	-0.017
93.96	-49.93	-0.017
94.00	-49.93	-0.017
94.05	-49.93	-0.017
94.09	-49.93	-0.017
94.13	-49.93	-0.017
94.16	-49.93	-0.017
94.20	-49.93	-0.017
94.25	-49.93	-0.017
94.29	-49.93	-0.017
94.33	-49.93	-0.017
94.36	-49.93	-0.017
94.40	-49.93	-0.017
94.45	-49.93	-0.017
94.49	-49.93	-0.017
94.53	-49.93	-0.017
94.56	-49.93	-0.017
94.60	-49.93	-0.017
94.65	-49.93	-0.017
94.69	-49.93	-0.017
94.73	-49.93	-0.017
94.76	-49.93	-0.017
94.80	-49.93	-0.017
94.85	-49.93	-0.017
94.89	-49.93	-0.017
94.93	-49.93	-0.017
94.96	-49.93	-0.017
95.00	-49.93	-0.017
95.05	-49.93	-0.017
95.09	-49.93	-0.017
95.13	-49.93	-0.017
95.16	-49.93	-0.017
95.20	-49.93	-0.017
95.25	-49.93	-0.017
95.29	-49.93	-0.017
95.33	-49.93	-0.017
95.36	-49.93	-0.017
95.40	-49.93	-0.017
95.45	-49.93	-0.017
95.49	-49.93	-0.017
95.53	-49.93	-0.017
95.56	-49.93	-0.017
95.60	-49.93	-0.017
95.65	-49.93	-0.017
95.69	-49.93	-0.017
95.73	-49.93	-0.017
95.76	-49.93	-0.017
95.80	-49.93	-0.017
95.85	-49.93	-0.017
95.89	-49.93	-0.017
95.93	-49.93	-0.017
95.96	-49.93	-0.017
96.00	-49.93	-0.017
96.05	-49.93	-0.017
96.09	-49.93	-0.017
96.13	-49.93	-0.017
96.16	-49.93	-0.017
96.20	-49.93	-0.017
96.25	-49.93	-0.017
96.29	-49.93	-0.017
96.33	-49.93	-0.017
96.36	-49.93	-0.017
96.40	-49.93	-0.017
96.45	-49.93	-0.017
96.49	-49.93	-0.017
96.53	-49.93	-0.017
96.56	-49.93	-0.017
96.60	-49.93	-0.017
96.65	-49.93	-0.017
96.69	-49.93	-0.017
96.73	-49.93	-0.017
96.76	-49.93	-0.017
96.80	-49.93	-0.017
96.85	-49.93	-0.017
96.89	-49.93	-0.017
96.93	-49.93	-0.017
96.96	-49.93	-0.017
97.00	-49.93	-0.017
97.05	-49.93	-0.017
97.09	-49.93	-0.017
97.13	-49.93	-0.017
97.16	-49.93	-0.017
97.20	-49.93	-0.017
97.25	-49.93	-0.017
97.29	-49.93	-0.017
97.33	-49.93	-0.017
97.36	-49.93	-0.017
97.40	-49.93	-0.017
97.45	-49.93	-0.017
97.49	-49.93	-0.017
97.53	-49.93	-0.017
97.56	-49.93	-0.017
97.60	-49.93	-0.017
97.65	-49.93	-0.017
97.69	-49.93	-0.017
97.73	-49.93	-0.017
97.76	-49.93	-0.017
97.80	-49.93	-0.017
97.85	-49.93	-0.017
97.89	-49.93	-0.017
97.93	-49.93	-0.017
97.96	-49.93	-0.017
98.00	-49.93	-0.017
98.05	-49.93	-0.017
98.09	-49.93	-0.017
98.13	-49.93	-0.017
98.16	-49.93	-0.017
98.20	-49.93	-0.017
98.25	-49.93	-0.017
98.29	-49.93	-0.017
98.33	-49.93	-0.017
98.36	-49.93	-0.017
98.40	-49.93	-0.017
98.45	-49.93	-0.017
98.49	-49.93	-0.017
98.53	-49.93	-0.017
98.56	-49.93	-0.017
98.60	-49.93	-0.017
98.65	-49.93	-0.017
98.69	-49.93	-0.017
98.73	-49.93	-0.017
98.76	-49.93	-0.017
98.80	-49.93	-0.017
98.85	-49.93	-0.017
98.89	-49.93	-0.017
98.93	-49.93	-0.017
98.96	-49.93	-0.017
99.00	-49.93	-0.017
99.05	-49.93	-0.017
99.09	-49.93	-0.017
99.13	-49.93	-0.017
99.16	-49.93	-0.017
99.20	-49.93	-0.017
99.25	-49.93	-0.017
99.29	-49.93	-0.017
99.33	-49.93	-0.017
99.36	-49.93	-0.017
99.40	-49.93	-0.017
99.45	-49.93	-0.017
99.49	-49.93	-0.017
99.53	-49.93	-0.017
99.56	-49.93	-0.017
99.60	-49.93	-0.017
99.65	-49.93	-0.017
99.69	-49.93	-0.017
99.73	-49.93	-0.017
99.76	-49.93	-0.017
99.80	-49.93	-0.017
99.85	-49.93	-0.017
99.89	-49.93	-0.017
99.93	-49.93	-0.017
99.96	-49.93	-0.017
100.00	-49.93	-0.017
100.05	-49.93	-0.017
100.09	-49.93	-0.017
100.13	-49.93	-0.017
100.16	-49.93	-0.017
[...]
171.64	-18.45	-0.062
171.71	-18.38	-0.062
171.78	-18.31	-0.063
171.85	-18.25	-0.063
171.92	-18.18	-0.063
171.98	-18.11	-0.063
172.05	-18.04	-0.064
172.12	-17.97	-0.064
172.19	-17.91	-0.064
172.26	-17.84	-0.064
172.33	-17.77	-0.065
172.40	-17.70	-0.065
172.46	-17.63	-0.065
172.53	-17.56	-0.065
172.60	-17.50	-0.066
172.67	-17.43	-0.066
172.74	-17.36	-0.066
172.80	-17.29	-0.067
172.87	-17.22	-0.067
172.94	-17.16	-0.067
173.01	-17.09	-0.068
173.08	-17.02	-0.068
173.15	-16.95	-0.068
173.22	-16.88	-0.069
173.28	-16.81	-0.069
173.35	-16.75	-0.070
173.42	-16.68	-0.070
173.49	-16.61	-0.070
173.56	-16.54	-0.071
173.63	-16.47	-0.071
173.69	-16.41	-0.072
173.76	-16.34	-0.072
173.83	-16.27	-0.072
173.90	-16.20	-0.073
173.97	-16.13	-0.073
174.03	-16.07	-0.074
174.10	-16.00	-0.074
174.17	-15.93	-0.075
174.24	-15.86	-0.075
174.31	-15.79	-0.076
174.38	-15.73	-0.076
174.45	-15.66	-0.077
174.51	-15.59	-0.077
174.58	-15.52	-0.078
174.65	-15.45	-0.078
174.72	-15.39	-0.079
174.79	-15.32	-0.080
174.85	-15.25	-0.080
174.92	-15.18	-0.081
174.99	-15.11	-0.081
175.06	-15.04	-0.082
175.13	-14.98	-0.083
175.20	-14.91	-0.083
175.27	-14.84	-0.084
175.33	-14.77	-0.084
175.40	-14.71	-0.085
175.47	-14.64	-0.086
175.54	-14.57	-0.087
175.61	-14.50	-0.087
175.68	-14.43	-0.088
175.74	-14.37	-0.089
175.81	-14.30	-0.089
175.88	-14.23	-0.090
175.95	-14.16	-0.091
176.02	-14.10	-0.092
176.08	-14.03	-0.093
176.15	-13.96	-0.094
176.22	-13.89	-0.094
176.29	-13.82	-0.095
176.36	-13.76	-0.096
176.43	-13.69	-0.097
176.50	-13.62	-0.098
176.56	-13.55	-0.099
176.63	-13.48	-0.100
176.70	-13.42	-0.101
176.77	-13.35	-0.102
176.84	-13.28	-0.103
176.90	-13.21	-0.104
176.97	-13.14	-0.105
177.04	-13.08	-0.107
177.11	-13.01	-0.108
177.18	-12.94	-0.109
177.25	-12.88	-0.110
177.32	-12.81	-0.111
177.38	-12.74	-0.112
177.45	-12.67	-0.113
177.52	-12.60	-0.115
177.59	-12.54	-0.116
177.66	-12.47	-0.117
177.73	-12.40	-0.119
177.79	-12.33	-0.120
177.86	-12.27	-0.122
177.93	-12.20	-0.123
178.00	-12.13	-0.124
178.07	-12.06	-0.126
178.13	-12.00	-0.127
178.20	-11.93	-0.129
178.27	-11.86	-0.130
178.34	-11.79	-0.132
178.41	-11.72	-0.133
178.48	-11.66	-0.135
178.55	-11.59	-0.137
178.61	-11.52	-0.139
178.68	-11.46	-0.141
178.75	-11.39	-0.143
178.82	-11.32	-0.145
178.89	-11.25	-0.148
178.95	-11.19	-0.150
179.02	-11.12	-0.153
179.09	-11.05	-0.156
179.16	-10.99	-0.159
179.23	-10.92	-0.161
179.30	-10.85	-0.164
179.37	-10.78	-0.167
179.43	-10.72	-0.171
179.50	-10.65	-0.174
179.57	-10.59	-0.177
179.64	-10.52	-0.181
179.71	-10.45	-0.184
179.78	-10.39	-0.187
179.84	-10.32	-0.191
179.91	-10.25	-0.195
179.98	-10.19	-0.199
180.05	-10.12	-0.203
180.12	-10.05	-0.207
180.18	-9.99	-0.211
180.25	-9.92	-0.216
180.32	-9.86	-0.220
180.39	-9.79	-0.225
180.46	-9.72	-0.230
180.53	-9.66	-0.235
180.60	-9.59	-0.240
180.66	-9.53	-0.245
180.73	-9.46	-0.251
180.80	-9.40	-0.257
180.87	-9.33	-0.263
180.94	-9.27	-0.269
181.00	-9.20	-0.275
181.07	-9.13	-0.282
181.14	-9.07	-0.288
181.21	-9.01	-0.295
181.28	-8.94	-0.302
181.35	-8.88	-0.310
181.42	-8.81	-0.317
181.48	-8.75	-0.325
181.55	-8.68	-0.333
181.62	-8.62	-0.341
181.69	-8.56	-0.350
181.76	-8.49	-0.359
181.83	-8.43	-0.369
181.89	-8.36	-0.378
181.96	-8.30	-0.388
182.03	-8.24	-0.398
182.10	-8.18	-0.408
182.17	-8.11	-0.419
182.23	-8.05	-0.430
182.30	-7.99	-0.441
182.37	-7.92	-0.453
182.44	-7.86	-0.464
182.51	-7.80	-0.476
182.58	-7.74	-0.488
182.65	-7.68	-0.499
182.71	-7.61	-0.511
182.78	-7.55	-0.522
182.85	-7.49	-0.532
182.92	-7.42	-0.542
182.99	-7.36	-0.549
183.05	-7.29	-0.553
183.12	-7.22	-0.553
183.19	-7.15	-0.539
183.26	-7.07	-0.512
183.33	-6.98	-0.473
183.40	-6.89	-0.425
183.47	-6.79	-0.369
183.53	-6.69	-0.305
183.60	-6.58	-0.233
183.67	-6.47	-0.154
183.74	-6.38	-0.103
183.81	-6.30	-0.076
183.88	-6.22	-0.064
183.94	-6.15	-0.058
184.01	-6.08	-0.055
184.08	-6.01	-0.054
184.15	-5.94	-0.053
184.22	-5.87	-0.052
184.28	-5.80	-0.052
184.35	-5.73	-0.051
184.42	-5.67	-0.051
184.49	-5.60	-0.051
184.56	-5.53	-0.050
184.63	-5.46	-0.050
184.70	-5.39	-0.050
184.76	-5.32	-0.050
184.83	-5.26	-0.050
184.90	-5.19	-0.050
184.97	-5.12	-0.050
185.04	-5.05	-0.050
185.10	-4.98	-0.050
185.17	-4.91	-0.050
185.24	-4.85	-0.050
185.31	-4.78	-0.050
185.38	-4.71	-0.050
185.45	-4.64	-0.050
185.52	-4.57	-0.050
185.58	-4.50	-0.050
185.65	-4.44	-0.050
185.72	-4.37	-0.050
185.79	-4.30	-0.050
185.86	-4.23	-0.050
185.93	-4.16	-0.050
185.99	-4.09	-0.050
186.06	-4.03	-0.050
186.13	-3.96	-0.050
186.20	-3.89	-0.050
186.27	-3.82	-0.050
186.33	-3.75	-0.050
186.40	-3.68	-0.050
186.47	-3.62	-0.050
186.54	-3.55	-0.050
186.61	-3.48	-0.050
186.68	-3.41	-0.050
186.75	-3.34	-0.050
186.81	-3.27	-0.050
186.88	-3.21	-0.050
186.95	-3.14	-0.050
187.02	-3.07	-0.050
187.09	-3.00	-0.050
187.15	-2.93	-0.050
187.22	-2.86	-0.050
187.29	-2.80	-0.050
187.36	-2.73	-0.050
187.43	-2.66	-0.050
187.50	-2.59	-0.050
187.57	-2.52	-0.050
187.63	-2.46	-0.050
187.70	-2.39	-0.050
187.77	-2.32	-0.050
187.84	-2.25	-0.050
187.91	-2.18	-0.050
187.98	-2.11	-0.050
188.04	-2.05	-0.050
188.11	-1.98	-0.050
188.18	-1.91	-0.049
188.25	-1.84	-0.049
188.32	-1.77	-0.049
188.38	-1.70	-0.049
188.45	-1.64	-0.049
188.52	-1.57	-0.050
188.59	-1.50	-0.050
188.66	-1.43	-0.050
188.73	-1.36	-0.050
188.80	-1.29	-0.050
188.86	-1.22	-0.050
188.93	-1.16	-0.050
189.00	-1.09	-0.049
189.07	-1.02	-0.049
189.14	-0.95	-0.050
189.20	-0.88	-0.050
189.27	-0.81	-0.050
189.34	-0.75	-0.050
189.41	-0.68	-0.050
189.48	-0.61	-0.049
189.55	-0.54	-0.049
189.62	-0.47	-0.049
189.68	-0.40	-0.050
189.75	-0.34	-0.050
189.82	-0.27	-0.050
189.89	-0.20	-0.050
189.96	-0.13	-0.050
190.03	-0.06	-0.050
190.09	0.00	-0.050
190.16	0.07	-0.050
190.23	0.14	-0.050
190.30	0.21	-0.050
190.37	0.28	-0.050
190.43	0.35	-0.050
190.50	0.42	-0.050
190.57	0.48	-0.050
190.64	0.55	-0.050
190.71	0.62	-0.050
190.78	0.69	-0.050
190.85	0.76	-0.050
190.91	0.82	-0.050
190.98	0.89	-0.050
191.05	0.96	-0.050
191.12	1.03	-0.050
191.19	1.10	-0.050
191.25	1.17	-0.050
191.32	1.24	-0.050
191.39	1.30	-0.050
191.46	1.37	-0.050
191.53	1.44	-0.050
191.60	1.51	-0.049
191.67	1.58	-0.049
191.73	1.65	-0.049
191.80	1.71	-0.049
191.87	1.78	-0.049
191.94	1.85	-0.049
192.01	1.92	-0.049
192.08	1.99	-0.050
192.14	2.05	-0.050
192.21	2.12	-0.050
192.28	2.19	-0.050
192.35	2.26	-0.050
192.42	2.33	-0.050
192.48	2.40	-0.050
192.55	2.46	-0.050
192.62	2.53	-0.050
192.69	2.60	-0.050
192.76	2.67	-0.050
192.83	2.74	-0.050
192.90	2.81	-0.050
192.96	2.87	-0.049
193.03	2.94	-0.049
193.10	3.01	-0.049
193.17	3.08	-0.049
193.24	3.15	-0.050
193.30	3.22	-0.049
193.37	3.28	-0.049
193.44	3.35	-0.049
193.51	3.42	-0.049
193.58	3.49	-0.049
193.65	3.56	-0.050
193.72	3.63	-0.050
193.78	3.69	-0.050
193.85	3.76	-0.050
193.92	3.83	-0.050
193.99	3.90	-0.050
194.06	3.97	-0.050
194.13	4.04	-0.050
194.19	4.10	-0.050
194.26	4.17	-0.050
194.33	4.24	-0.050
194.40	4.31	-0.050
194.47	4.38	-0.050
194.53	4.45	-0.050
194.60	4.51	-0.050
194.67	4.58	-0.050
194.74	4.65	-0.050
194.81	4.72	-0.050
194.88	4.79	-0.050
194.95	4.85	-0.050
195.01	4.92	-0.050
195.08	4.99	-0.050
195.15	5.06	-0.050
195.22	5.13	-0.050
195.29	5.20	-0.050
195.35	5.27	-0.050
195.42	5.33	-0.050
195.49	5.40	-0.050
195.56	5.47	-0.050
195.63	5.54	-0.050
195.70	5.61	-0.050
195.77	5.68	-0.050
195.83	5.75	-0.050
195.90	5.81	-0.050
195.97	5.88	-0.050
196.04	5.95	-0.050
196.11	6.02	-0.050
196.18	6.09	-0.050
196.24	6.15	-0.050
196.31	6.22	-0.050
196.38	6.29	-0.050
196.45	6.36	-0.050
196.52	6.43	-0.050
196.58	6.50	-0.050
196.65	6.56	-0.050
196.72	6.63	-0.050
196.79	6.70	-0.050
196.86	6.77	-0.050
196.93	6.84	-0.050
197.00	6.91	-0.049
197.06	6.97	-0.049
197.13	7.04	-0.049
197.20	7.11	-0.049
197.27	7.18	-0.049
197.34	7.25	-0.049
197.40	7.32	-0.049
197.47	7.38	-0.049
197.54	7.45	-0.049
197.61	7.52	-0.049
197.68	7.59	-0.050
197.75	7.66	-0.050
197.82	7.73	-0.049
197.88	7.79	-0.049
197.95	7.86	-0.049
198.02	7.93	-0.049
198.09	8.00	-0.050
198.16	8.07	-0.050
198.23	8.13	-0.050
198.29	8.20	-0.050
198.36	8.27	-0.050
198.43	8.34	-0.050
198.50	8.41	-0.050
198.57	8.48	-0.050
198.63	8.55	-0.050
198.70	8.61	-0.050
198.77	8.68	-0.049
198.84	8.75	-0.049
198.91	8.82	-0.049
198.98	8.89	-0.049
199.05	8.95	-0.050
199.11	9.02	-0.050
199.18	9.09	-0.050
199.25	9.16	-0.050
199.32	9.23	-0.050
199.39	9.30	-0.050
199.45	9.37	-0.050
199.52	9.43	-0.050
199.59	9.50	-0.050
199.66	9.57	-0.049
199.73	9.64	-0.049
199.80	9.71	-0.049
199.87	9.78	-0.049
199.93	9.84	-0.049
200.00	9.91	-0.049
200.07	9.98	-0.049
200.14	10.05	-0.049
200.21	10.12	-0.049
200.28	10.18	-0.049
200.34	10.25	-0.049
200.41	10.32	-0.049
200.48	10.39	-0.049
200.55	10.46	-0.049
200.62	10.53	-0.050
200.68	10.60	-0.050
200.75	10.66	-0.050
200.82	10.73	-0.050
200.89	10.80	-0.050
200.96	10.87	-0.050
201.03	10.94	-0.049
201.10	11.00	-0.049
201.16	11.07	-0.049
201.23	11.14	-0.049
201.30	11.21	-0.049
201.37	11.28	-0.049
201.44	11.35	-0.049
201.50	11.41	-0.049
201.57	11.48	-0.049
201.64	11.55	-0.049
201.71	11.62	-0.049
201.78	11.69	-0.049
201.85	11.76	-0.049
201.92	11.82	-0.049
201.98	11.89	-0.049
202.05	11.96	-0.049
202.12	12.03	-0.049
202.19	12.10	-0.049
202.26	12.17	-0.049
202.33	12.23	-0.049
202.39	12.30	-0.049
202.46	12.37	-0.049
202.53	12.44	-0.049
202.60	12.51	-0.049
202.67	12.58	-0.049
202.73	12.64	-0.049
202.80	12.71	-0.049
202.87	12.78	-0.049
202.94	12.85	-0.049
203.01	12.92	-0.049
203.08	12.99	-0.049
203.15	13.05	-0.049
203.21	13.12	-0.049
203.28	13.19	-0.049
203.35	13.26	-0.049
203.42	13.33	-0.049
203.49	13.40	-0.049
203.55	13.46	-0.049
203.62	13.53	-0.049
203.69	13.60	-0.049
203.76	13.67	-0.049
203.83	13.74	-0.049
203.90	13.81	-0.049
203.97	13.87	-0.049
204.03	13.94	-0.049
204.10	14.01	-0.049
204.17	14.08	-0.049
204.24	14.15	-0.049
204.31	14.21	-0.049
204.38	14.28	-0.049
204.44	14.35	-0.049
204.51	14.42	-0.049
204.58	14.49	-0.049
204.65	14.56	-0.049
204.72	14.63	-0.049
204.78	14.69	-0.049
204.85	14.76	-0.049
204.92	14.83	-0.049
204.99	14.90	-0.049
205.06	14.97	-0.049
205.13	15.04	-0.049
205.20	15.10	-0.049
205.26	15.17	-0.049
205.33	15.24	-0.049
205.40	15.31	-0.049
205.47	15.38	-0.049
205.54	15.45	-0.049
205.60	15.51	-0.049
205.67	15.58	-0.049
205.74	15.65	-0.049
205.81	15.72	-0.049
205.88	15.79	-0.049
205.95	15.86	-0.049
206.02	15.92	-0.049
206.08	15.99	-0.049
206.15	16.06	-0.049
206.22	16.13	-0.049
206.29	16.20	-0.049
206.36	16.26	-0.049
206.43	16.33	-0.049
206.49	16.40	-0.049
206.56	16.47	-0.049
206.63	16.54	-0.049
206.70	16.61	-0.049
206.77	16.67	-0.049
206.83	16.74	-0.049
206.90	16.81	-0.049
206.97	16.88	-0.049
207.04	16.95	-0.049
207.11	17.02	-0.049
207.18	17.08	-0.049
207.25	17.15	-0.049
207.31	17.22	-0.049
207.38	17.29	-0.049
207.45	17.36	-0.049
207.52	17.43	-0.049
207.59	17.49	-0.049
207.65	17.56	-0.049
207.72	17.63	-0.049
207.79	17.70	-0.049
207.86	17.77	-0.049
207.93	17.84	-0.049
208.00	17.90	-0.049
208.07	17.97	-0.049
208.13	18.04	-0.049
208.20	18.11	-0.049
208.27	18.18	-0.049
208.34	18.25	-0.049
208.41	18.31	-0.049
208.48	18.38	-0.049
208.54	18.45	-0.049
208.61	18.52	-0.049
208.68	18.59	-0.049
208.75	18.66	-0.049
208.82	18.72	-0.049
208.88	18.79	-0.049
208.95	18.86	-0.049
209.02	18.93	-0.049
209.09	19.00	-0.049
209.16	19.07	-0.049
209.23	19.13	-0.049
209.30	19.20	-0.049
209.36	19.27	-0.049
209.43	19.34	-0.049
209.50	19.41	-0.049
209.57	19.48	-0.049
209.64	19.54	-0.049
209.70	19.61	-0.049
209.77	19.68	-0.049
209.84	19.75	-0.049
209.91	19.82	-0.049
209.98	19.89	-0.049
210.05	19.95	-0.049
210.12	20.02	-0.049
210.18	20.09	-0.049
210.25	20.16	-0.049
210.32	20.23	-0.049
210.39	20.30	-0.049
210.46	20.36	-0.049
210.53	20.43	-0.049
210.59	20.50	-0.049
210.66	20.57	-0.049
210.73	20.64	-0.049
210.80	20.71	-0.049
210.87	20.77	-0.049
210.93	20.84	-0.049
211.00	20.91	-0.049
211.07	20.98	-0.049
211.14	21.05	-0.049
211.21	21.12	-0.049
211.28	21.18	-0.049
211.35	21.25	-0.049
211.41	21.32	-0.049
211.48	21.39	-0.049
211.55	21.46	-0.049
211.62	21.52	-0.049
211.69	21.59	-0.049
211.75	21.66	-0.049
211.82	21.73	-0.049
211.89	21.80	-0.050
211.96	21.87	-0.050
212.03	21.93	-0.050
212.10	22.00	-0.050
212.17	22.07	-0.050
212.23	22.14	-0.050
212.30	22.21	-0.050
212.37	22.28	-0.049
212.44	22.35	-0.049
212.51	22.41	-0.049
212.58	22.48	-0.049
212.64	22.55	-0.049
212.71	22.62	-0.049
212.78	22.69	-0.049
212.85	22.75	-0.049
212.92	22.82	-0.049
212.98	22.89	-0.049
213.05	22.96	-0.049
213.12	23.03	-0.049
213.19	23.10	-0.049
213.26	23.16	-0.049
213.33	23.23	-0.049
213.40	23.30	-0.049
213.46	23.37	-0.049
213.53	23.44	-0.049
213.60	23.51	-0.049
213.67	23.58	-0.049
213.74	23.64	-0.049
213.80	23.71	-0.049
213.87	23.78	-0.049
213.94	23.85	-0.049
214.01	23.92	-0.049
214.08	23.98	-0.049
214.15	24.05	-0.049
214.22	24.12	-0.049
214.28	24.19	-0.049
214.35	24.26	-0.049
214.42	24.33	-0.049
214.49	24.39	-0.049
214.56	24.46	-0.049
214.63	24.53	-0.049
214.69	24.60	-0.049
214.76	24.67	-0.049
214.83	24.74	-0.049
214.90	24.80	-0.049
214.97	24.87	-0.049
215.03	24.94	-0.049
215.10	25.01	-0.049
215.17	25.08	-0.049
215.24	25.15	-0.049
215.31	25.21	-0.049
215.38	25.28	-0.049
215.45	25.35	-0.049
215.51	25.42	-0.049
215.58	25.49	-0.049
215.65	25.56	-0.049
215.72	25.62	-0.049
215.79	25.69	-0.049
215.85	25.76	-0.049
215.92	25.83	-0.050
215.99	25.90	-0.050
216.06	25.97	-0.049
216.13	26.04	-0.049
216.20	26.10	-0.049
216.27	26.17	-0.049
216.33	26.24	-0.049
216.40	26.31	-0.049
216.47	26.38	-0.049
216.54	26.44	-0.049
216.61	26.51	-0.049
216.68	26.58	-0.049
216.74	26.65	-0.049
216.81	26.72	-0.049
216.88	26.78	-0.049
216.95	26.85	-0.049
217.02	26.92	-0.049
217.08	26.99	-0.049
217.15	27.06	-0.049
217.22	27.13	-0.049
217.29	27.20	-0.049
217.36	27.26	-0.049
217.43	27.33	-0.049
217.50	27.40	-0.049
217.56	27.47	-0.049
217.63	27.54	-0.049
217.70	27.60	-0.049
217.77	27.67	-0.049
217.84	27.74	-0.049
217.90	27.81	-0.049
217.97	27.88	-0.049
218.04	27.95	-0.049
218.11	28.01	-0.049
218.18	28.08	-0.049
218.25	28.15	-0.049
218.32	28.22	-0.049
218.38	28.29	-0.049
218.45	28.36	-0.049
218.52	28.42	-0.049
218.59	28.49	-0.049
218.66	28.56	-0.049
218.73	28.63	-0.049
218.79	28.70	-0.049
218.86	28.77	-0.049
218.93	28.83	-0.049
219.00	28.90	-0.049
219.07	28.97	-0.049
219.13	29.04	-0.049
219.20	29.11	-0.049
219.27	29.18	-0.049
219.34	29.24	-0.049
219.41	29.31	-0.049
219.48	29.38	-0.049
219.55	29.45	-0.049
219.61	29.52	-0.049
219.68	29.59	-0.049
219.75	29.65	-0.049
219.82	29.72	-0.049
219.89	29.79	-0.049
219.95	29.86	-0.049
220.02	29.93	-0.049
220.09	30.00	-0.049
220.16	30.06	-0.049
220.23	30.13	-0.049
220.30	30.20	-0.049
220.37	30.27	-0.049
220.43	30.34	-0.049
220.50	30.41	-0.049
220.57	30.47	-0.049
220.64	30.54	-0.049
220.71	30.61	-0.049
220.78	30.68	-0.049
220.84	30.75	-0.049
220.91	30.82	-0.049
220.98	30.89	-0.049
221.05	30.95	-0.049
221.12	31.02	-0.049
221.18	31.09	-0.049
221.25	31.16	-0.049
221.32	31.23	-0.049
221.39	31.30	-0.049
221.46	31.36	-0.049
221.53	31.43	-0.049
221.60	31.50	-0.049
221.66	31.57	-0.049
221.73	31.64	-0.049
221.80	31.70	-0.049
221.87	31.77	-0.049
221.94	31.84	-0.049
222.00	31.91	-0.049
222.07	31.98	-0.049
222.14	32.05	-0.049
222.21	32.11	-0.049
222.28	32.18	-0.049
222.35	32.25	-0.049
222.42	32.32	-0.049
222.48	32.39	-0.049
222.55	32.46	-0.049
222.62	32.53	-0.049
222.69	32.59	-0.049
222.76	32.66	-0.049
222.83	32.73	-0.049
222.89	32.80	-0.049
222.96	32.87	-0.049
223.03	32.93	-0.049
223.10	33.00	-0.049
223.17	33.07	-0.049
223.23	33.14	-0.049
223.30	33.21	-0.049
223.37	33.28	-0.049
223.44	33.34	-0.049
223.51	33.41	-0.049
223.58	33.48	-0.049
223.65	33.55	-0.049
223.71	33.62	-0.049
223.78	33.69	-0.049
223.85	33.75	-0.049
223.92	33.82	-0.049
223.99	33.89	-0.049
224.05	33.96	-0.049
224.12	34.03	-0.049
224.19	34.10	-0.049
224.26	34.16	-0.049
224.33	34.23	-0.049
224.40	34.30	-0.049
224.47	34.37	-0.049
224.53	34.44	-0.049
224.60	34.51	-0.049
224.67	34.57	-0.049
224.74	34.64	-0.049
224.81	34.71	-0.049
224.88	34.78	-0.049
224.94	34.85	-0.049
225.01	34.92	-0.049
225.08	34.99	-0.049
225.15	35.05	-0.049
225.22	35.12	-0.049
225.28	35.19	-0.049
225.35	35.26	-0.049
225.42	35.33	-0.049
225.49	35.39	-0.049
225.56	35.46	-0.049
225.63	35.53	-0.049
225.70	35.60	-0.049
225.76	35.67	-0.049
225.83	35.74	-0.049
225.90	35.81	-0.049
225.97	35.87	-0.049
226.04	35.94	-0.049
226.10	36.01	-0.049
226.17	36.08	-0.049
226.24	36.15	-0.049
226.31	36.21	-0.049
226.38	36.28	-0.049
226.45	36.35	-0.049
226.52	36.42	-0.049
226.58	36.49	-0.049
226.65	36.55	-0.049
226.72	36.62	-0.049
226.79	36.69	-0.049
226.86	36.76	-0.049
226.93	36.83	-0.049
226.99	36.90	-0.049
227.06	36.97	-0.049
227.13	37.03	-0.049
227.20	37.10	-0.049
227.27	37.17	-0.049
227.33	37.24	-0.049
227.40	37.31	-0.049
227.47	37.38	-0.049
227.54	37.44	-0.049
227.61	37.51	-0.049
227.68	37.58	-0.049
227.75	37.65	-0.049
227.81	37.72	-0.049
227.88	37.78	-0.049
227.95	37.85	-0.049
228.02	37.92	-0.049
228.09	37.99	-0.049
228.15	38.06	-0.049
228.22	38.13	-0.049
228.29	38.19	-0.049
228.36	38.26	-0.049
228.43	38.33	-0.049
228.50	38.40	-0.049
228.57	38.47	-0.049
228.63	38.54	-0.049
228.70	38.60	-0.049
228.77	38.67	-0.049
228.84	38.74	-0.049
228.91	38.81	-0.049
228.98	38.88	-0.049
229.04	38.95	-0.049
229.11	39.02	-0.049
229.18	39.08	-0.049
229.25	39.15	-0.049
229.32	39.22	-0.049
229.38	39.29	-0.049
229.45	39.36	-0.049
229.52	39.43	-0.049
229.59	39.49	-0.049
229.66	39.56	-0.049
229.73	39.63	-0.049
229.80	39.70	-0.049
229.86	39.77	-0.049
229.93	39.83	-0.049
230.00	39.90	-0.049
230.07	39.97	-0.049
230.14	40.04	-0.049
230.20	40.11	-0.049
230.27	40.18	-0.049
230.34	40.24	-0.049
230.41	40.31	-0.049
230.48	40.38	-0.049
230.55	40.45	-0.049
230.62	40.52	-0.049
230.68	40.59	-0.049
230.75	40.65	-0.049
230.82	40.72	-0.049
230.89	40.79	-0.049
230.96	40.86	-0.049
231.03	40.93	-0.049
231.09	41.00	-0.049
231.16	41.06	-0.049
231.23	41.13	-0.049
231.30	41.20	-0.049
231.37	41.27	-0.049
231.43	41.34	-0.049
231.50	41.41	-0.049
231.57	41.47	-0.049
231.64	41.54	-0.049
231.71	41.61	-0.049
231.78	41.68	-0.049
231.85	41.75	-0.049
231.91	41.82	-0.049
231.98	41.88	-0.049
232.05	41.95	-0.049
232.12	42.02	-0.049
232.19	42.09	-0.049
232.25	42.16	-0.049
232.32	42.23	-0.049
232.39	42.30	-0.049
232.46	42.36	-0.049
232.53	42.43	-0.049
232.60	42.50	-0.049
232.67	42.57	-0.049
232.73	42.64	-0.049
232.80	42.70	-0.049
232.87	42.77	-0.049
232.94	42.84	-0.049
233.01	42.91	-0.049
233.08	42.98	-0.049
233.14	43.04	-0.049
233.21	43.11	-0.049
233.28	43.18	-0.049
233.35	43.25	-0.049
233.42	43.32	-0.049
233.48	43.39	-0.049
233.55	43.46	-0.049
233.62	43.52	-0.049
233.69	43.59	-0.049
233.76	43.66	-0.049
233.83	43.73	-0.049
233.90	43.80	-0.049
233.96	43.87	-0.049
234.03	43.93	-0.049
234.10	44.00	-0.049
234.17	44.07	-0.049
234.24	44.14	-0.049
234.30	44.21	-0.049
234.37	44.28	-0.049
234.44	44.34	-0.049
234.51	44.41	-0.049
234.58	44.48	-0.049
234.65	44.55	-0.049
234.72	44.62	-0.049
234.78	44.69	-0.049
234.85	44.75	-0.049
234.92	44.82	-0.049
234.99	44.89	-0.049
235.06	44.96	-0.049
235.13	45.03	-0.049
235.19	45.10	-0.049
235.26	45.16	-0.049
235.33	45.23	-0.049
235.40	45.30	-0.049
235.47	45.37	-0.049
235.53	45.44	-0.049
235.60	45.50	-0.049
235.67	45.57	-0.049
235.74	45.64	-0.049
235.81	45.71	-0.049
235.88	45.78	-0.049
235.95	45.85	-0.049
236.01	45.91	-0.049
236.08	45.98	-0.049
236.15	46.05	-0.049
236.22	46.12	-0.049
236.29	46.19	-0.049
236.35	46.26	-0.049
236.42	46.33	-0.049
236.49	46.39	-0.049
236.56	46.46	-0.049
236.63	46.53	-0.049
236.70	46.60	-0.049
236.77	46.67	-0.049
236.83	46.73	-0.049
236.90	46.80	-0.049
236.97	46.87	-0.049
237.04	46.94	-0.049
237.11	47.01	-0.049
237.18	47.07	-0.049
237.24	47.15	-0.049
237.31	47.21	-0.049
237.38	47.28	-0.049
237.45	47.35	-0.049
237.52	47.42	-0.049
237.58	47.49	-0.049
237.65	47.55	-0.049
237.72	47.62	-0.049
237.79	47.69	-0.049
237.86	47.76	-0.049
237.93	47.83	-0.049
238.00	47.90	-0.049
238.06	47.96	-0.049
238.13	48.03	-0.049
238.20	48.10	-0.049
238.27	48.17	-0.049
238.34	48.24	-0.049
238.40	48.31	-0.049
238.47	48.37	-0.049
238.54	48.44	-0.049
238.61	48.51	-0.049
238.68	48.58	-0.049
238.75	48.65	-0.049
238.82	48.72	-0.049
238.88	48.78	-0.049
238.95	48.85	-0.049
239.02	48.92	-0.049
239.09	48.99	-0.049
239.16	49.06	-0.049
239.23	49.13	-0.049
239.29	49.19	-0.049
239.36	49.26	-0.049
239.43	49.33	-0.049
239.50	49.40	-0.049
239.57	49.47	-0.049
239.63	49.54	-0.049
239.70	49.60	-0.049
239.77	49.67	-0.049
239.84	49.74	-0.049
239.91	49.81	-0.049
239.98	49.88
240.00